Workbook
Name act_cal_base_address: activity_calendar!$P$2
Name ADDR_OTHERS: misc!$S$3
Name BILLING_SCHEDULE_ADDRESS: 'Single Action'!#REF!
Name BILLING_SCHEDULE_ADDRESS_1PHASE: 'Single Action'!$Q$2
Name BILLING_SCHEDULE_BASE_1PHASE: 'Single Action'!$Q$2
Name BILLINGPARAM_BASEADDRESS: billing_param!#REF!
Name billingparamaddress: billing_param!#REF!
Name BILLINGPARAMBASEADDRESS_1PHASE: billing_param!$O$3
Name DAILYLOAD_BASEADDRESS_3PHASE: dailyload!#REF!
Name DAILYLOADSURVEYBASEADDRESS_1phase: dailyload!$S$1
Name DLMS_EEPROM_START_ADDRESS__in_HEX: Event_logs!#REF!
Name DLNS_NUMBYTESTOSTORE_3PHASE: dailyload!#REF!
Name DLS_MAXDAYS: dailyload!$J$1
Name DLS_MAXDAYS_60: dailyload!$L$1
Name DLS_numbytestostore_1phase: dailyload!$P$1
Name INSTANTANEOUS_BASEADDR: 'Instataneous Param'!#REF!
Name INSTANTANEOUS_BASEADDR_1PHASE: 'Instataneous Param'!$F$3
Name LOAD_SURVEY_BASE_ADRESS: 'block load survey'!$S$1
Name LOAD_SURVEY_BASE_ADRESS_1phase: 'block load survey'!$S$1
Name LOADSURVEY_REF_ADDRESS: 'block load survey'!$V$1
Name loadsurveybaseaddress: 'block load survey'!#REF!
Name loadsurveyref_address: 'block load survey'!#REF!
Name MD_NUMBYTES: billing_param!#REF!
Name MD_SLOTS: billing_param!#REF!
Name MISC_OTHERS: misc!#REF!
Name numberofbytes_to_store_1phase: billing_param!$L$3
Name numberofbytes_tostore_1phase: 'block load survey'!$P$1
Name NUMBYTES: 'block load survey'!#REF!
Name PASSWORD_BASE_ADDRESS: password!#REF!
Name PASSWORD_BASE_ADDRESS_1PHASE: password!$P$3
Name sizeof_event_buffer: Event_logs!$D$5
Name slots_per_day_1phase: 'block load survey'!$L$1
Name SLOTSPERDAY: 'block load survey'!#REF!

Sheet Overview
A2: 1 | B2: This is a EEPROM map for SY7T108 DLMS (1 phase) | C2: 12 Billing History,
C3: 2 seasons
C4: 5 Time Zones
C5: 60 days Load survey

Sheet Event_logs
C3: 1-phase Tamper data storage in EEPROM ( 20+50 events) (event log of 30 bytes)
G4: Available address for DLMS | H4: A02
B5: code reference | C5: sizeof_event buffer | D5: 30 | G5: ADDRESS_INITMETER | H5: =H4 -> A02
C6: Event ID status | D6: EEPROM address (hex) | E6: EEPROM address (dec) | F6: number of storage bytes | G6: Type of Tamper | H6: Parameter | I6: EEPROM offset index | J6: Remark | K6: event log storage in EEPROM from @EVENTLOG_BASE_ADDRESS
B7: EVENTIDS_BASEADDRESS | C7: event_ID_status (1,2) | D7: A04 | E7: =HEX2DEC(D7) -> 2564 | F7: 0 | G7: voltages | H7: NA (RPhase_missing) | J7: NOT USED | K7: parameter | L7: number of bytes
C8: event_ID_status (3,4) | D8: =DEC2HEX(SUM(HEX2DEC(D7))+F7) -> A04 | E8: =HEX2DEC(D8) -> 2564 | F8: 0 | H8: NA (YPhase_missing) | J8: NOT USED | K8: date+time | L8: 12
C9: event_ID_status (5,6) | D9: =DEC2HEX(SUM(HEX2DEC(D8))+F8) -> A04 | E9: =HEX2DEC(D9) -> 2564 | F9: 0 | H9: NA (BPhase_missing) | J9: NOT USED | K9: event code | L9: 2
C10: event_ID_status (7,8) | D10: =DEC2HEX(SUM(HEX2DEC(D9))+F9) -> A04 | E10: =HEX2DEC(D10) -> 2564 | F10: 0 | H10: NA (Over Voltage) | J10: NOT USED | K10: Measured Current | L10: 4
C11: event_ID_status (9,10) | D11: =DEC2HEX(SUM(HEX2DEC(D10))+F10) -> A04 | E11: =HEX2DEC(D11) -> 2564 | F11: 1 | H11: (Low Voltage) | I11: 0 | K11: Phase Voltage | L11: 4
C12: event_ID_status (11,12) | D12: =DEC2HEX(SUM(HEX2DEC(D11))+F11) -> A05 | E12: =HEX2DEC(D12) -> 2565 | F12: 0 | H12: NA (Voltage Unbalance) | J12: NOT USED | K12: PF | L12: 4
C13: eventID status(51,52) | D13: =DEC2HEX(SUM(HEX2DEC(D12))+F12) -> A05 | E13: =HEX2DEC(D13) -> 2565 | F13: 0 | G13: currents | J13: NOT USED | K13: KWh | L13: 4
C14: eventID status(53,54) | D14: =DEC2HEX(SUM(HEX2DEC(D13))+F13) -> A05 | E14: =HEX2DEC(D14) -> 2565 | F14: 0 | H14: NA (R CT reverse) | J14: NOT USED | K14: Total | L14: =SUM(L8:L13) -> 30
C15: eventID status(55,56) | D15: =DEC2HEX(SUM(HEX2DEC(D14))+F14) -> A05 | E15: =HEX2DEC(D15) -> 2565 | F15: 0 | H15: NA (Y CT reverse) | J15: NOT USED
C16: eventID status(57,58) | D16: =DEC2HEX(SUM(HEX2DEC(D15))+F15) -> A05 | E16: =HEX2DEC(D16) -> 2565 | F16: 0 | H16: NA (B CT reverse) | J16: NOT USED
C17: eventID status(59,60) | D17: =DEC2HEX(SUM(HEX2DEC(D16))+F16) -> A05 | E17: =HEX2DEC(D17) -> 2565 | F17: 0 | H17: NA (R CT Open) | J17: NOT USED
C18: eventID status(61,62) | D18: =DEC2HEX(SUM(HEX2DEC(D17))+F17) -> A05 | E18: =HEX2DEC(D18) -> 2565 | F18: 0 | H18: NA (Y CT Open) | J18: NOT USED
C19: eventID status(63,64) | D19: =DEC2HEX(SUM(HEX2DEC(D18))+F18) -> A05 | E19: =HEX2DEC(D19) -> 2565 | F19: 0 | H19: NA (B CT Open) | J19: NOT USED
C20: eventID status(65,66) | D20: =DEC2HEX(SUM(HEX2DEC(D19))+F19) -> A05 | E20: =HEX2DEC(D20) -> 2565 | F20: 0 | H20: NA (Current Unbalance) | J20: NOT USED
C21: eventID status(67,68) | D21: =DEC2HEX(SUM(HEX2DEC(D20))+F20) -> A05 | E21: =HEX2DEC(D21) -> 2565 | F21: 0 | H21: NA (Over Current) | J21: NOT USED
C22: eventID status(69,70) | D22: =DEC2HEX(SUM(HEX2DEC(D21))+F21) -> A05 | E22: =HEX2DEC(D22) -> 2565 | F22: 1 | H22: Earth Loading | I22: =SUM(1+I11) -> 1
C23: eventID status(101,102) | D23: =DEC2HEX(SUM(HEX2DEC(D22))+F22) -> A06 | E23: =HEX2DEC(D23) -> 2566 | F23: 1 | G23: power | H23: POWER_FAIL | I23: =SUM(1+I22) -> 2
C24: eventID status(151) | D24: =DEC2HEX(SUM(HEX2DEC(D23))+F23) -> A07 | E24: =HEX2DEC(D24) -> 2567 | F24: 1 | G24: transaction related | H24: RTC | I24: =SUM(1+I23) -> 3
C25: eventID status(152) | D25: =DEC2HEX(SUM(HEX2DEC(D24))+F24) -> A08 | E25: =HEX2DEC(D25) -> 2568 | F25: 1 | H25: DEMAND_INT | I25: =SUM(1+I24) -> 4
C26: eventID status(153) | D26: =DEC2HEX(SUM(HEX2DEC(D25))+F25) -> A09 | E26: =HEX2DEC(D26) -> 2569 | F26: 1 | H26: PROFILE_CAPTURE | I26: =SUM(1+I25) -> 5
C27: eventID status(154) | D27: =DEC2HEX(SUM(HEX2DEC(D26))+F26) -> A0A | E27: =HEX2DEC(D27) -> 2570 | F27: 1 | H27: SINGLE_ACTION | I27: =SUM(1+I26) -> 6
C28: eventID status(155) | D28: =DEC2HEX(SUM(HEX2DEC(D27))+F27) -> A0B | E28: =HEX2DEC(D28) -> 2571 | F28: 1 | H28: ACTIVITY_CALENDER | I28: =SUM(1+I27) -> 7
C29: eventID status(201,202) | D29: =DEC2HEX(SUM(HEX2DEC(D28))+F28) -> A0C | E29: =HEX2DEC(D29) -> 2572 | F29: 1 | G29: magnetic | H29: MAGNET | I29: =SUM(1+I28) -> 8
C30: eventID status(203,204) | D30: =DEC2HEX(SUM(HEX2DEC(D29))+F29) -> A0D | E30: =HEX2DEC(D30) -> 2573 | F30: 1 | H30: NEUTRAL_DISTURBANCE | I30: =SUM(1+I29) -> 9
C31: eventID status(205,206) | D31: =DEC2HEX(SUM(HEX2DEC(D30))+F30) -> A0E | E31: =HEX2DEC(D31) -> 2574 | F31: 1 | G31: NOT USED | H31: VERY_LOWPF | I31: =SUM(1+I30) -> 10 | J31: NOT USED
C32: eventID status(207,208) | D32: =DEC2HEX(SUM(HEX2DEC(D31))+F31) -> A0F | E32: =HEX2DEC(D32) -> 2575 | F32: 1 | H32: Neutral missing | I32: =SUM(1+I31) -> 11
C33: eventID status(251) | D33: =DEC2HEX(SUM(HEX2DEC(D32))+F32) -> A10 | E33: =HEX2DEC(D33) -> 2576 | F33: 1 | G33: coveropen | H33: METER_OPEN | I33: =SUM(1+I32) -> 12
C34: eventID status(301,302) | D34: =DEC2HEX(SUM(HEX2DEC(D33))+F33) -> A11 | E34: =HEX2DEC(D34) -> 2577 | F34: 1 | H34: METER_CONNECT | I34: =SUM(1+I33) -> 13 | J34: NOT USED
C36: TamperCount | D36: =DEC2HEX(SUM(HEX2DEC(D34))+F34) -> A12 | E36: =HEX2DEC(D36) -> 2578 | F36: 1 | H36: tamper count | I36: =SUM(1+I34) -> 14
B37: EVENTTYPES_BASEADDRESS | C37: voltage_event_code | D37: =DEC2HEX(SUM(HEX2DEC(D36))+F36) -> A13 | E37: =HEX2DEC(D37) -> 2579 | F37: 2 | H37: voltage event | I37: =SUM(1+I36) -> 15
C38: current_event_code | D38: =DEC2HEX(SUM(HEX2DEC(D37))+F37) -> A15 | E38: =HEX2DEC(D38) -> 2581 | F38: 2 | H38: current event | I38: =SUM(1+I37) -> 16
C39: Power_event_code | D39: =DEC2HEX(SUM(HEX2DEC(D38))+F38) -> A17 | E39: =HEX2DEC(D39) -> 2583 | F39: 2 | H39: power event | I39: =SUM(1+I38) -> 17
C40: transaction_event_code | D40: =DEC2HEX(SUM(HEX2DEC(D39))+F39) -> A19 | E40: =HEX2DEC(D40) -> 2585 | F40: 2 | H40: rtansaction event | I40: =SUM(1+I39) -> 18
C41: magnetic_event_code | D41: =DEC2HEX(SUM(HEX2DEC(D40))+F40) -> A1B | E41: =HEX2DEC(D41) -> 2587 | F41: 2 | H41: magnetic event | I41: =SUM(1+I40) -> 19
C42: coveropen_event_code | D42: =DEC2HEX(SUM(HEX2DEC(D41))+F41) -> A1D | E42: =HEX2DEC(D42) -> 2589 | F42: 2 | H42: cover open event | I42: =SUM(1+I41) -> 20
C43: control_event_code | D43: =DEC2HEX(SUM(HEX2DEC(D42))+F42) -> A1F | E43: =HEX2DEC(D43) -> 2591 | F43: 2 | G43: UN USED | H43: control event | I43: =SUM(1+I42) -> 21
...

Sheet block load survey
A1: block load survey parameters : 1-phase | K1: slots_per_day_1phase | L1: 48 | O1: numberofbytes_to store_1phase | P1: 42 | R1: LOAD SURVEY BASE ADRESS | S1: =G75 -> 1283 | U1: LOAD_SURVEY_REF_ADDRESS | V1: =Event_logs!D116 -> 1255
B2: day | C2: hour | D2: mins | E2: slotnum | F2: Offset from base address (hex) | G2: stored @ EEPROM address in HEX | H2: stored @ EEPROM address in DEC | I2: day | J2: hour | K2: mins | L2: slotnum | M2: Offset from base address (hex) | N2: stored @ EEPROM address in HEX | O2: stored @ EEPROM address in DEC | P2: day | Q2: hour | R2: mins | S2: slotnum | T2: Offset from base address (hex) | U2: stored @ EEPROM address in HEX | V2: stored @ EEPROM address in DEC | X2: day | Y2: hour | Z2: mins | AA2: slotnum | AB2: Offset from base address (hex) | AC2: stored @ EEPROM address in HEX | AD2: stored @ EEPROM address in DEC | AF2: day | AG2: hour | AH2: mins | AI2: slotnum | AJ2: Offset from base address (hex) | AK2: stored @ EEPROM address in HEX | AL2: stored @ EEPROM address in DEC | AN2: day | AO2: hour | AP2: mins | AQ2: slotnum | AR2: Offset from base address (hex) | AS2: stored @ EEPROM address in HEX | AT2: stored @ EEPROM address in DEC | AV2: day | AW2: hour | AX2: mins | AY2: slotnum | AZ2: Offset from base address (hex) | BA2: stored @ EEPROM address in HEX | BB2: stored @ EEPROM address in DEC
B3: 0 | C3: 0 | D3: 0 | E3: =IF(D3=0,(2*C3),(2*C3+1)) -> 0 | F3: =DEC2HEX(SUM((B3*slots_per_day_1phase)+E3)*numberofbytes_tostore_1phase) -> 0 | G3: =DEC2HEX(SUM(HEX2DEC(LOAD_SURVEY_BASE_ADRESS),HEX2DEC(F3))) -> 1283 | I3: 1 | J3: 0 | K3: 0 | L3: =IF(K3=0,(2*J3),(2*J3+1)) -> 0 | M3: =DEC2HEX(SUM((I3*slots_per_day_1phase)+L3)*numberofbytes_tostore_1phase) -> 7E0 | N3: =DEC2HEX(SUM(HEX2DEC(LOAD_SURVEY_BASE_ADRESS),HEX2DEC(M3))) -> 1A63 | P3: =SUM(I3+1) -> 2 | Q3: 0 | R3: 0 | S3: =IF(R3=0,(2*Q3),(2*Q3+1)) -> 0 | T3: =DEC2HEX(SUM((P3*slots_per_day_1phase)+S3)*numberofbytes_tostore_1phase) -> FC0 | U3: =DEC2HEX(SUM(HEX2DEC(LOAD_SURVEY_BASE_ADRESS),HEX2DEC(T3))) -> 2243 | X3: 7 | Y3: 0 | Z3: 0 | AA3: =IF(Z3=0,(2*Y3),(2*Y3+1)) -> 0 | AB3: =DEC2HEX(SUM((X3*slots_per_day_1phase)+AA3)*numberofbytes_tostore_1phase) -> 3720 | AC3: =DEC2HEX(SUM(HEX2DEC(LOAD_SURVEY_BASE_ADRESS),HEX2DEC(AB3))) -> 49A3 | AF3: 21 | AG3: 0 | AH3: 0 | AI3: =IF(AH3=0,(2*AG3),(2*AG3+1)) -> 0 | AJ3: =DEC2HEX(SUM((AF3*slots_per_day_1phase)+AI3)*numberofbytes_tostore_1phase) -> A560 | AK3: =DEC2HEX(SUM(HEX2DEC(LOAD_SURVEY_BASE_ADRESS),HEX2DEC(AJ3))) -> B7E3 | AN3: 34 | AO3: 0 | AP3: 0 | AQ3: =IF(AP3=0,(2*AO3),(2*AO3+1)) -> 0 | AR3: =DEC2HEX(SUM((AN3*slots_per_day_1phase)+AQ3)*numberofbytes_tostore_1phase) -> 10BC0 | AS3: =DEC2HEX(SUM(HEX2DEC(LOAD_SURVEY_BASE_ADRESS),HEX2DEC(AR3))) -> 11E43 | AV3: 60 | AW3: 0 | AX3: 0 | AY3: =IF(AX3=0,(2*AW3),(2*AW3+1)) -> 0 | AZ3: =DEC2HEX(SUM((AV3*slots_per_day_1phase)+AY3)*numberofbytes_tostore_1phase) -> 1D880 | BA3: =DEC2HEX(SUM(HEX2DEC(LOAD_SURVEY_BASE_ADRESS),HEX2DEC(AZ3))) -> 1EB03
B4: 0 | C4: =C3 -> 0 | D4: =IF(D3=30,0,30) -> 30 | E4: =IF(D4=0,(2*C4),(2*C4+1)) -> 1 | F4: =DEC2HEX(SUM((B4*slots_per_day_1phase)+E4)*numberofbytes_tostore_1phase) -> 2A | G4: =DEC2HEX(SUM(HEX2DEC(LOAD_SURVEY_BASE_ADRESS),HEX2DEC(F4))) -> 12AD | I4: 1 | J4: =J3 -> 0 | K4: =IF(K3=30,0,30) -> 30 | L4: =IF(K4=0,(2*J4),(2*J4+1)) -> 1 | M4: =DEC2HEX(SUM((I4*slots_per_day_1phase)+L4)*numberofbytes_tostore_1phase) -> 80A | N4: =DEC2HEX(SUM(HEX2DEC(LOAD_SURVEY_BASE_ADRESS),HEX2DEC(M4))) -> 1A8D | P4: =SUM(P3+0) -> 2 | Q4: =Q3 -> 0 | R4: =IF(R3=30,0,30) -> 30 | S4: =IF(R4=0,(2*Q4),(2*Q4+1)) -> 1 | T4: =DEC2HEX(SUM((P4*slots_per_day_1phase)+S4)*numberofbytes_tostore_1phase) -> FEA | U4: =DEC2HEX(SUM(HEX2DEC(LOAD_SURVEY_BASE_ADRESS),HEX2DEC(T4))) -> 226D | X4: =SUM(X3+0) -> 7 | Y4: =Y3 -> 0 | Z4: =IF(Z3=30,0,30) -> 30 | AA4: =IF(Z4=0,(2*Y4),(2*Y4+1)) -> 1 | AB4: =DEC2HEX(SUM((X4*slots_per_day_1phase)+AA4)*numberofbytes_tostore_1phase) -> 374A | AC4: =DEC2HEX(SUM(HEX2DEC(LOAD_SURVEY_BASE_ADRESS),HEX2DEC(AB4))) -> 49CD | AF4: =SUM(AF3+0) -> 21 | AG4: =AG3 -> 0 | AH4: =IF(AH3=30,0,30) -> 30 | AI4: =IF(AH4=0,(2*AG4),(2*AG4+1)) -> 1 | AJ4: =DEC2HEX(SUM((AF4*slots_per_day_1phase)+AI4)*numberofbytes_tostore_1phase) -> A58A | AK4: =DEC2HEX(SUM(HEX2DEC(LOAD_SURVEY_BASE_ADRESS),HEX2DEC(AJ4))) -> B80D | AN4: =SUM(AN3+0) -> 34 | AO4: =AO3 -> 0 | AP4: =IF(AP3=30,0,30) -> 30 | AQ4: =IF(AP4=0,(2*AO4),(2*AO4+1)) -> 1 | AR4: =DEC2HEX(SUM((AN4*slots_per_day_1phase)+AQ4)*numberofbytes_tostore_1phase) -> 10BEA | AS4: =DEC2HEX(SUM(HEX2DEC(LOAD_SURVEY_BASE_ADRESS),HEX2DEC(AR4))) -> 11E6D | AV4: 60 | AW4: =AW3 -> 0 | AX4: =IF(AX3=30,0,30) -> 30 | AY4: =IF(AX4=0,(2*AW4),(2*AW4+1)) -> 1 | AZ4: =DEC2HEX(SUM((AV4*slots_per_day_1phase)+AY4)*numberofbytes_tostore_1phase) -> 1D8AA | BA4: =DEC2HEX(SUM(HEX2DEC(LOAD_SURVEY_BASE_ADRESS),HEX2DEC(AZ4))) -> 1EB2D
B5: 0 | C5: =SUM(C4+1) -> 1 | D5: =IF(D4=30,0,30) -> 0 | E5: =IF(D5=0,(2*C5),(2*C5+1)) -> 2 | F5: =DEC2HEX(SUM((B5*slots_per_day_1phase)+E5)*numberofbytes_tostore_1phase) -> 54 | G5: =DEC2HEX(SUM(HEX2DEC(LOAD_SURVEY_BASE_ADRESS),HEX2DEC(F5))) -> 12D7 | I5: 1 | J5: =SUM(J4+1) -> 1 | K5: =IF(K4=30,0,30) -> 0 | L5: =IF(K5=0,(2*J5),(2*J5+1)) -> 2 | M5: =DEC2HEX(SUM((I5*slots_per_day_1phase)+L5)*numberofbytes_tostore_1phase) -> 834 | N5: =DEC2HEX(SUM(HEX2DEC(LOAD_SURVEY_BASE_ADRESS),HEX2DEC(M5))) -> 1AB7 | P5: =SUM(P4+0) -> 2 | Q5: =SUM(Q4+1) -> 1 | R5: =IF(R4=30,0,30) -> 0 | S5: =IF(R5=0,(2*Q5),(2*Q5+1)) -> 2 | T5: =DEC2HEX(SUM((P5*slots_per_day_1phase)+S5)*numberofbytes_tostore_1phase) -> 1014 | U5: =DEC2HEX(SUM(HEX2DEC(LOAD_SURVEY_BASE_ADRESS),HEX2DEC(T5))) -> 2297 | X5: =SUM(X4+0) -> 7 | Y5: =SUM(Y4+1) -> 1 | Z5: =IF(Z4=30,0,30) -> 0 | AA5: =IF(Z5=0,(2*Y5),(2*Y5+1)) -> 2 | AB5: =DEC2HEX(SUM((X5*slots_per_day_1phase)+AA5)*numberofbytes_tostore_1phase) -> 3774 | AC5: =DEC2HEX(SUM(HEX2DEC(LOAD_SURVEY_BASE_ADRESS),HEX2DEC(AB5))) -> 49F7 | AF5: =SUM(AF4+0) -> 21 | AG5: =SUM(AG4+1) -> 1 | AH5: =IF(AH4=30,0,30) -> 0 | AI5: =IF(AH5=0,(2*AG5),(2*AG5+1)) -> 2 | AJ5: =DEC2HEX(SUM((AF5*slots_per_day_1phase)+AI5)*numberofbytes_tostore_1phase) -> A5B4 | AK5: =DEC2HEX(SUM(HEX2DEC(LOAD_SURVEY_BASE_ADRESS),HEX2DEC(AJ5))) -> B837 | AN5: =SUM(AN4+0) -> 34 | AO5: =SUM(AO4+1) -> 1 | AP5: =IF(AP4=30,0,30) -> 0 | AQ5: =IF(AP5=0,(2*AO5),(2*AO5+1)) -> 2 | AR5: =DEC2HEX(SUM((AN5*slots_per_day_1phase)+AQ5)*numberofbytes_tostore_1phase) -> 10C14 | AS5: =DEC2HEX(SUM(HEX2DEC(LOAD_SURVEY_BASE_ADRESS),HEX2DEC(AR5))) -> 11E97 | AV5: 60 | AW5: =SUM(AW4+1) -> 1 | AX5: =IF(AX4=30,0,30) -> 0 | AY5: =IF(AX5=0,(2*AW5),(2*AW5+1)) -> 2 | AZ5: =DEC2HEX(SUM((AV5*slots_per_day_1phase)+AY5)*numberofbytes_tostore_1phase) -> 1D8D4 | BA5: =DEC2HEX(SUM(HEX2DEC(LOAD_SURVEY_BASE_ADRESS),HEX2DEC(AZ5))) -> 1EB57
B6: 0 | C6: =C5 -> 1 | D6: =IF(D5=30,0,30) -> 30 | E6: =SUM(E5+1) -> 3 | F6: =DEC2HEX(SUM((B6*slots_per_day_1phase)+E6)*numberofbytes_tostore_1phase) -> 7E | G6: =DEC2HEX(SUM(HEX2DEC(LOAD_SURVEY_BASE_ADRESS),HEX2DEC(F6))) -> 1301 | I6: 1 | J6: =J5 -> 1 | K6: =IF(K5=30,0,30) -> 30 | L6: =SUM(L5+1) -> 3 | M6: =DEC2HEX(SUM((I6*slots_per_day_1phase)+L6)*numberofbytes_tostore_1phase) -> 85E | N6: =DEC2HEX(SUM(HEX2DEC(LOAD_SURVEY_BASE_ADRESS),HEX2DEC(M6))) -> 1AE1 | P6: =SUM(P5+0) -> 2 | Q6: =Q5 -> 1 | R6: =IF(R5=30,0,30) -> 30 | S6: =SUM(S5+1) -> 3 | T6: =DEC2HEX(SUM((P6*slots_per_day_1phase)+S6)*numberofbytes_tostore_1phase) -> 103E | U6: =DEC2HEX(SUM(HEX2DEC(LOAD_SURVEY_BASE_ADRESS),HEX2DEC(T6))) -> 22C1 | X6: =SUM(X5+0) -> 7 | Y6: =Y5 -> 1 | Z6: =IF(Z5=30,0,30) -> 30 | AA6: =SUM(AA5+1) -> 3 | AB6: =DEC2HEX(SUM((X6*slots_per_day_1phase)+AA6)*numberofbytes_tostore_1phase) -> 379E | AC6: =DEC2HEX(SUM(HEX2DEC(LOAD_SURVEY_BASE_ADRESS),HEX2DEC(AB6))) -> 4A21 | AF6: =SUM(AF5+0) -> 21 | AG6: =AG5 -> 1 | AH6: =IF(AH5=30,0,30) -> 30 | AI6: =SUM(AI5+1) -> 3 | AJ6: =DEC2HEX(SUM((AF6*slots_per_day_1phase)+AI6)*numberofbytes_tostore_1phase) -> A5DE | AK6: =DEC2HEX(SUM(HEX2DEC(LOAD_SURVEY_BASE_ADRESS),HEX2DEC(AJ6))) -> B861 | AN6: =SUM(AN5+0) -> 34 | AO6: =AO5 -> 1 | AP6: =IF(AP5=30,0,30) -> 30 | AQ6: =SUM(AQ5+1) -> 3 | AR6: =DEC2HEX(SUM((AN6*slots_per_day_1phase)+AQ6)*numberofbytes_tostore_1phase) -> 10C3E | AS6: =DEC2HEX(SUM(HEX2DEC(LOAD_SURVEY_BASE_ADRESS),HEX2DEC(AR6))) -> 11EC1 | AV6: 60 | AW6: =AW5 -> 1 | AX6: =IF(AX5=30,0,30) -> 30 | AY6: =SUM(AY5+1) -> 3 | AZ6: =DEC2HEX(SUM((AV6*slots_per_day_1phase)+AY6)*numberofbytes_tostore_1phase) -> 1D8FE | BA6: =DEC2HEX(SUM(HEX2DEC(LOAD_SURVEY_BASE_ADRESS),HEX2DEC(AZ6))) -> 1EB81
B7: 0 | C7: =SUM(C5+1) -> 2 | D7: =IF(D6=30,0,30) -> 0 | E7: =SUM(E6+1) -> 4 | F7: =DEC2HEX(SUM((B7*slots_per_day_1phase)+E7)*numberofbytes_tostore_1phase) -> A8 | G7: =DEC2HEX(SUM(HEX2DEC(LOAD_SURVEY_BASE_ADRESS),HEX2DEC(F7))) -> 132B | I7: 1 | J7: =SUM(J5+1) -> 2 | K7: =IF(K6=30,0,30) -> 0 | L7: =SUM(L6+1) -> 4 | M7: =DEC2HEX(SUM((I7*slots_per_day_1phase)+L7)*numberofbytes_tostore_1phase) -> 888 | N7: =DEC2HEX(SUM(HEX2DEC(LOAD_SURVEY_BASE_ADRESS),HEX2DEC(M7))) -> 1B0B | P7: =SUM(P6+0) -> 2 | Q7: =SUM(Q5+1) -> 2 | R7: =IF(R6=30,0,30) -> 0 | S7: =SUM(S6+1) -> 4 | T7: =DEC2HEX(SUM((P7*slots_per_day_1phase)+S7)*numberofbytes_tostore_1phase) -> 1068 | U7: =DEC2HEX(SUM(HEX2DEC(LOAD_SURVEY_BASE_ADRESS),HEX2DEC(T7))) -> 22EB | X7: =SUM(X6+0) -> 7 | Y7: =SUM(Y5+1) -> 2 | Z7: =IF(Z6=30,0,30) -> 0 | AA7: =SUM(AA6+1) -> 4 | AB7: =DEC2HEX(SUM((X7*slots_per_day_1phase)+AA7)*numberofbytes_tostore_1phase) -> 37C8 | AC7: =DEC2HEX(SUM(HEX2DEC(LOAD_SURVEY_BASE_ADRESS),HEX2DEC(AB7))) -> 4A4B | AF7: =SUM(AF6+0) -> 21 | AG7: =SUM(AG5+1) -> 2 | AH7: =IF(AH6=30,0,30) -> 0 | AI7: =SUM(AI6+1) -> 4 | AJ7: =DEC2HEX(SUM((AF7*slots_per_day_1phase)+AI7)*numberofbytes_tostore_1phase) -> A608 | AK7: =DEC2HEX(SUM(HEX2DEC(LOAD_SURVEY_BASE_ADRESS),HEX2DEC(AJ7))) -> B88B | AN7: =SUM(AN6+0) -> 34 | AO7: =SUM(AO5+1) -> 2 | AP7: =IF(AP6=30,0,30) -> 0 | AQ7: =SUM(AQ6+1) -> 4 | AR7: =DEC2HEX(SUM((AN7*slots_per_day_1phase)+AQ7)*numberofbytes_tostore_1phase) -> 10C68 | AS7: =DEC2HEX(SUM(HEX2DEC(LOAD_SURVEY_BASE_ADRESS),HEX2DEC(AR7))) -> 11EEB | AV7: 60 | AW7: =SUM(AW5+1) -> 2 | AX7: =IF(AX6=30,0,30) -> 0 | AY7: =SUM(AY6+1) -> 4 | AZ7: =DEC2HEX(SUM((AV7*slots_per_day_1phase)+AY7)*numberofbytes_tostore_1phase) -> 1D928 | BA7: =DEC2HEX(SUM(HEX2DEC(LOAD_SURVEY_BASE_ADRESS),HEX2DEC(AZ7))) -> 1EBAB
B8: 0 | C8: =C7 -> 2 | D8: =IF(D7=30,0,30) -> 30 | E8: =SUM(E7+1) -> 5 | F8: =DEC2HEX(SUM((B8*slots_per_day_1phase)+E8)*numberofbytes_tostore_1phase) -> D2 | G8: =DEC2HEX(SUM(HEX2DEC(LOAD_SURVEY_BASE_ADRESS),HEX2DEC(F8))) -> 1355 | I8: 1 | J8: =J7 -> 2 | K8: =IF(K7=30,0,30) -> 30 | L8: =SUM(L7+1) -> 5 | M8: =DEC2HEX(SUM((I8*slots_per_day_1phase)+L8)*numberofbytes_tostore_1phase) -> 8B2 | N8: =DEC2HEX(SUM(HEX2DEC(LOAD_SURVEY_BASE_ADRESS),HEX2DEC(M8))) -> 1B35 | P8: =SUM(P7+0) -> 2 | Q8: =Q7 -> 2 | R8: =IF(R7=30,0,30) -> 30 | S8: =SUM(S7+1) -> 5 | T8: =DEC2HEX(SUM((P8*slots_per_day_1phase)+S8)*numberofbytes_tostore_1phase) -> 1092 | U8: =DEC2HEX(SUM(HEX2DEC(LOAD_SURVEY_BASE_ADRESS),HEX2DEC(T8))) -> 2315 | X8: =SUM(X7+0) -> 7 | Y8: =Y7 -> 2 | Z8: =IF(Z7=30,0,30) -> 30 | AA8: =SUM(AA7+1) -> 5 | AB8: =DEC2HEX(SUM((X8*slots_per_day_1phase)+AA8)*numberofbytes_tostore_1phase) -> 37F2 | AC8: =DEC2HEX(SUM(HEX2DEC(LOAD_SURVEY_BASE_ADRESS),HEX2DEC(AB8))) -> 4A75 | AF8: =SUM(AF7+0) -> 21 | AG8: =AG7 -> 2 | AH8: =IF(AH7=30,0,30) -> 30 | AI8: =SUM(AI7+1) -> 5 | AJ8: =DEC2HEX(SUM((AF8*slots_per_day_1phase)+AI8)*numberofbytes_tostore_1phase) -> A632 | AK8: =DEC2HEX(SUM(HEX2DEC(LOAD_SURVEY_BASE_ADRESS),HEX2DEC(AJ8))) -> B8B5 | AN8: =SUM(AN7+0) -> 34 | AO8: =AO7 -> 2 | AP8: =IF(AP7=30,0,30) -> 30 | AQ8: =SUM(AQ7+1) -> 5 | AR8: =DEC2HEX(SUM((AN8*slots_per_day_1phase)+AQ8)*numberofbytes_tostore_1phase) -> 10C92 | AS8: =DEC2HEX(SUM(HEX2DEC(LOAD_SURVEY_BASE_ADRESS),HEX2DEC(AR8))) -> 11F15 | AV8: 60 | AW8: =AW7 -> 2 | AX8: =IF(AX7=30,0,30) -> 30 | AY8: =SUM(AY7+1) -> 5 | AZ8: =DEC2HEX(SUM((AV8*slots_per_day_1phase)+AY8)*numberofbytes_tostore_1phase) -> 1D952 | BA8: =DEC2HEX(SUM(HEX2DEC(LOAD_SURVEY_BASE_ADRESS),HEX2DEC(AZ8))) -> 1EBD5
B9: 0 | C9: =SUM(C7+1) -> 3 | D9: =IF(D8=30,0,30) -> 0 | E9: =SUM(E8+1) -> 6 | F9: =DEC2HEX(SUM((B9*slots_per_day_1phase)+E9)*numberofbytes_tostore_1phase) -> FC | G9: =DEC2HEX(SUM(HEX2DEC(LOAD_SURVEY_BASE_ADRESS),HEX2DEC(F9))) -> 137F | I9: 1 | J9: =SUM(J7+1) -> 3 | K9: =IF(K8=30,0,30) -> 0 | L9: =SUM(L8+1) -> 6 | M9: =DEC2HEX(SUM((I9*slots_per_day_1phase)+L9)*numberofbytes_tostore_1phase) -> 8DC | N9: =DEC2HEX(SUM(HEX2DEC(LOAD_SURVEY_BASE_ADRESS),HEX2DEC(M9))) -> 1B5F | P9: =SUM(P8+0) -> 2 | Q9: =SUM(Q7+1) -> 3 | R9: =IF(R8=30,0,30) -> 0 | S9: =SUM(S8+1) -> 6 | T9: =DEC2HEX(SUM((P9*slots_per_day_1phase)+S9)*numberofbytes_tostore_1phase) -> 10BC | U9: =DEC2HEX(SUM(HEX2DEC(LOAD_SURVEY_BASE_ADRESS),HEX2DEC(T9))) -> 233F | X9: =SUM(X8+0) -> 7 | Y9: =SUM(Y7+1) -> 3 | Z9: =IF(Z8=30,0,30) -> 0 | AA9: =SUM(AA8+1) -> 6 | AB9: =DEC2HEX(SUM((X9*slots_per_day_1phase)+AA9)*numberofbytes_tostore_1phase) -> 381C | AC9: =DEC2HEX(SUM(HEX2DEC(LOAD_SURVEY_BASE_ADRESS),HEX2DEC(AB9))) -> 4A9F | AF9: =SUM(AF8+0) -> 21 | AG9: =SUM(AG7+1) -> 3 | AH9: =IF(AH8=30,0,30) -> 0 | AI9: =SUM(AI8+1) -> 6 | AJ9: =DEC2HEX(SUM((AF9*slots_per_day_1phase)+AI9)*numberofbytes_tostore_1phase) -> A65C | AK9: =DEC2HEX(SUM(HEX2DEC(LOAD_SURVEY_BASE_ADRESS),HEX2DEC(AJ9))) -> B8DF | AN9: =SUM(AN8+0) -> 34 | AO9: =SUM(AO7+1) -> 3 | AP9: =IF(AP8=30,0,30) -> 0 | AQ9: =SUM(AQ8+1) -> 6 | AR9: =DEC2HEX(SUM((AN9*slots_per_day_1phase)+AQ9)*numberofbytes_tostore_1phase) -> 10CBC | AS9: =DEC2HEX(SUM(HEX2DEC(LOAD_SURVEY_BASE_ADRESS),HEX2DEC(AR9))) -> 11F3F | AV9: 60 | AW9: =SUM(AW7+1) -> 3 | AX9: =IF(AX8=30,0,30) -> 0 | AY9: =SUM(AY8+1) -> 6 | AZ9: =DEC2HEX(SUM((AV9*slots_per_day_1phase)+AY9)*numberofbytes_tostore_1phase) -> 1D97C | BA9: =DEC2HEX(SUM(HEX2DEC(LOAD_SURVEY_BASE_ADRESS),HEX2DEC(AZ9))) -> 1EBFF
B10: 0 | C10: =C9 -> 3 | D10: =IF(D9=30,0,30) -> 30 | E10: =SUM(E9+1) -> 7 | F10: =DEC2HEX(SUM((B10*slots_per_day_1phase)+E10)*numberofbytes_tostore_1phase) -> 126 | G10: =DEC2HEX(SUM(HEX2DEC(LOAD_SURVEY_BASE_ADRESS),HEX2DEC(F10))) -> 13A9 | I10: 1 | J10: =J9 -> 3 | K10: =IF(K9=30,0,30) -> 30 | L10: =SUM(L9+1) -> 7 | M10: =DEC2HEX(SUM((I10*slots_per_day_1phase)+L10)*numberofbytes_tostore_1phase) -> 906 | N10: =DEC2HEX(SUM(HEX2DEC(LOAD_SURVEY_BASE_ADRESS),HEX2DEC(M10))) -> 1B89 | P10: =SUM(P9+0) -> 2 | Q10: =Q9 -> 3 | R10: =IF(R9=30,0,30) -> 30 | S10: =SUM(S9+1) -> 7 | T10: =DEC2HEX(SUM((P10*slots_per_day_1phase)+S10)*numberofbytes_tostore_1phase) -> 10E6 | U10: =DEC2HEX(SUM(HEX2DEC(LOAD_SURVEY_BASE_ADRESS),HEX2DEC(T10))) -> 2369 | X10: =SUM(X9+0) -> 7 | Y10: =Y9 -> 3 | Z10: =IF(Z9=30,0,30) -> 30 | AA10: =SUM(AA9+1) -> 7 | AB10: =DEC2HEX(SUM((X10*slots_per_day_1phase)+AA10)*numberofbytes_tostore_1phase) -> 3846 | AC10: =DEC2HEX(SUM(HEX2DEC(LOAD_SURVEY_BASE_ADRESS),HEX2DEC(AB10))) -> 4AC9 | AF10: =SUM(AF9+0) -> 21 | AG10: =AG9 -> 3 | AH10: =IF(AH9=30,0,30) -> 30 | AI10: =SUM(AI9+1) -> 7 | AJ10: =DEC2HEX(SUM((AF10*slots_per_day_1phase)+AI10)*numberofbytes_tostore_1phase) -> A686 | AK10: =DEC2HEX(SUM(HEX2DEC(LOAD_SURVEY_BASE_ADRESS),HEX2DEC(AJ10))) -> B909 | AN10: =SUM(AN9+0) -> 34 | AO10: =AO9 -> 3 | AP10: =IF(AP9=30,0,30) -> 30 | AQ10: =SUM(AQ9+1) -> 7 | AR10: =DEC2HEX(SUM((AN10*slots_per_day_1phase)+AQ10)*numberofbytes_tostore_1phase) -> 10CE6 | AS10: =DEC2HEX(SUM(HEX2DEC(LOAD_SURVEY_BASE_ADRESS),HEX2DEC(AR10))) -> 11F69 | AV10: 60 | AW10: =AW9 -> 3 | AX10: =IF(AX9=30,0,30) -> 30 | AY10: =SUM(AY9+1) -> 7 | AZ10: =DEC2HEX(SUM((AV10*slots_per_day_1phase)+AY10)*numberofbytes_tostore_1phase) -> 1D9A6 | BA10: =DEC2HEX(SUM(HEX2DEC(LOAD_SURVEY_BASE_ADRESS),HEX2DEC(AZ10))) -> 1EC29
B11: 0 | C11: =SUM(C9+1) -> 4 | D11: =IF(D10=30,0,30) -> 0 | E11: =SUM(E10+1) -> 8 | F11: =DEC2HEX(SUM((B11*slots_per_day_1phase)+E11)*numberofbytes_tostore_1phase) -> 150 | G11: =DEC2HEX(SUM(HEX2DEC(LOAD_SURVEY_BASE_ADRESS),HEX2DEC(F11))) -> 13D3 | I11: 1 | J11: =SUM(J9+1) -> 4 | K11: =IF(K10=30,0,30) -> 0 | L11: =SUM(L10+1) -> 8 | M11: =DEC2HEX(SUM((I11*slots_per_day_1phase)+L11)*numberofbytes_tostore_1phase) -> 930 | N11: =DEC2HEX(SUM(HEX2DEC(LOAD_SURVEY_BASE_ADRESS),HEX2DEC(M11))) -> 1BB3 | P11: =SUM(P10+0) -> 2 | Q11: =SUM(Q9+1) -> 4 | R11: =IF(R10=30,0,30) -> 0 | S11: =SUM(S10+1) -> 8 | T11: =DEC2HEX(SUM((P11*slots_per_day_1phase)+S11)*numberofbytes_tostore_1phase) -> 1110 | U11: =DEC2HEX(SUM(HEX2DEC(LOAD_SURVEY_BASE_ADRESS),HEX2DEC(T11))) -> 2393 | X11: =SUM(X10+0) -> 7 | Y11: =SUM(Y9+1) -> 4 | Z11: =IF(Z10=30,0,30) -> 0 | AA11: =SUM(AA10+1) -> 8 | AB11: =DEC2HEX(SUM((X11*slots_per_day_1phase)+AA11)*numberofbytes_tostore_1phase) -> 3870 | AC11: =DEC2HEX(SUM(HEX2DEC(LOAD_SURVEY_BASE_ADRESS),HEX2DEC(AB11))) -> 4AF3 | AF11: =SUM(AF10+0) -> 21 | AG11: =SUM(AG9+1) -> 4 | AH11: =IF(AH10=30,0,30) -> 0 | AI11: =SUM(AI10+1) -> 8 | AJ11: =DEC2HEX(SUM((AF11*slots_per_day_1phase)+AI11)*numberofbytes_tostore_1phase) -> A6B0 | AK11: =DEC2HEX(SUM(HEX2DEC(LOAD_SURVEY_BASE_ADRESS),HEX2DEC(AJ11))) -> B933 | AN11: =SUM(AN10+0) -> 34 | AO11: =SUM(AO9+1) -> 4 | AP11: =IF(AP10=30,0,30) -> 0 | AQ11: =SUM(AQ10+1) -> 8 | AR11: =DEC2HEX(SUM((AN11*slots_per_day_1phase)+AQ11)*numberofbytes_tostore_1phase) -> 10D10 | AS11: =DEC2HEX(SUM(HEX2DEC(LOAD_SURVEY_BASE_ADRESS),HEX2DEC(AR11))) -> 11F93 | AV11: 60 | AW11: =SUM(AW9+1) -> 4 | AX11: =IF(AX10=30,0,30) -> 0 | AY11: =SUM(AY10+1) -> 8 | AZ11: =DEC2HEX(SUM((AV11*slots_per_day_1phase)+AY11)*numberofbytes_tostore_1phase) -> 1D9D0 | BA11: =DEC2HEX(SUM(HEX2DEC(LOAD_SURVEY_BASE_ADRESS),HEX2DEC(AZ11))) -> 1EC53
B12: 0 | C12: =C11 -> 4 | D12: =IF(D11=30,0,30) -> 30 | E12: =SUM(E11+1) -> 9 | F12: =DEC2HEX(SUM((B12*slots_per_day_1phase)+E12)*numberofbytes_tostore_1phase) -> 17A | G12: =DEC2HEX(SUM(HEX2DEC(LOAD_SURVEY_BASE_ADRESS),HEX2DEC(F12))) -> 13FD | I12: 1 | J12: =J11 -> 4 | K12: =IF(K11=30,0,30) -> 30 | L12: =SUM(L11+1) -> 9 | M12: =DEC2HEX(SUM((I12*slots_per_day_1phase)+L12)*numberofbytes_tostore_1phase) -> 95A | N12: =DEC2HEX(SUM(HEX2DEC(LOAD_SURVEY_BASE_ADRESS),HEX2DEC(M12))) -> 1BDD | P12: =SUM(P11+0) -> 2 | Q12: =Q11 -> 4 | R12: =IF(R11=30,0,30) -> 30 | S12: =SUM(S11+1) -> 9 | T12: =DEC2HEX(SUM((P12*slots_per_day_1phase)+S12)*numberofbytes_tostore_1phase) -> 113A | U12: =DEC2HEX(SUM(HEX2DEC(LOAD_SURVEY_BASE_ADRESS),HEX2DEC(T12))) -> 23BD | X12: =SUM(X11+0) -> 7 | Y12: =Y11 -> 4 | Z12: =IF(Z11=30,0,30) -> 30 | AA12: =SUM(AA11+1) -> 9 | AB12: =DEC2HEX(SUM((X12*slots_per_day_1phase)+AA12)*numberofbytes_tostore_1phase) -> 389A | AC12: =DEC2HEX(SUM(HEX2DEC(LOAD_SURVEY_BASE_ADRESS),HEX2DEC(AB12))) -> 4B1D | AF12: =SUM(AF11+0) -> 21 | AG12: =AG11 -> 4 | AH12: =IF(AH11=30,0,30) -> 30 | AI12: =SUM(AI11+1) -> 9 | AJ12: =DEC2HEX(SUM((AF12*slots_per_day_1phase)+AI12)*numberofbytes_tostore_1phase) -> A6DA | AK12: =DEC2HEX(SUM(HEX2DEC(LOAD_SURVEY_BASE_ADRESS),HEX2DEC(AJ12))) -> B95D | AN12: =SUM(AN11+0) -> 34 | AO12: =AO11 -> 4 | AP12: =IF(AP11=30,0,30) -> 30 | AQ12: =SUM(AQ11+1) -> 9 | AR12: =DEC2HEX(SUM((AN12*slots_per_day_1phase)+AQ12)*numberofbytes_tostore_1phase) -> 10D3A | AS12: =DEC2HEX(SUM(HEX2DEC(LOAD_SURVEY_BASE_ADRESS),HEX2DEC(AR12))) -> 11FBD | AV12: 60 | AW12: =AW11 -> 4 | AX12: =IF(AX11=30,0,30) -> 30 | AY12: =SUM(AY11+1) -> 9 | AZ12: =DEC2HEX(SUM((AV12*slots_per_day_1phase)+AY12)*numberofbytes_tostore_1phase) -> 1D9FA | BA12: =DEC2HEX(SUM(HEX2DEC(LOAD_SURVEY_BASE_ADRESS),HEX2DEC(AZ12))) -> 1EC7D
B13: 0 | C13: =SUM(C11+1) -> 5 | D13: =IF(D12=30,0,30) -> 0 | E13: =SUM(E12+1) -> 10 | F13: =DEC2HEX(SUM((B13*slots_per_day_1phase)+E13)*numberofbytes_tostore_1phase) -> 1A4 | G13: =DEC2HEX(SUM(HEX2DEC(LOAD_SURVEY_BASE_ADRESS),HEX2DEC(F13))) -> 1427 | I13: 1 | J13: =SUM(J11+1) -> 5 | K13: =IF(K12=30,0,30) -> 0 | L13: =SUM(L12+1) -> 10 | M13: =DEC2HEX(SUM((I13*slots_per_day_1phase)+L13)*numberofbytes_tostore_1phase) -> 984 | N13: =DEC2HEX(SUM(HEX2DEC(LOAD_SURVEY_BASE_ADRESS),HEX2DEC(M13))) -> 1C07 | P13: =SUM(P12+0) -> 2 | Q13: =SUM(Q11+1) -> 5 | R13: =IF(R12=30,0,30) -> 0 | S13: =SUM(S12+1) -> 10 | T13: =DEC2HEX(SUM((P13*slots_per_day_1phase)+S13)*numberofbytes_tostore_1phase) -> 1164 | U13: =DEC2HEX(SUM(HEX2DEC(LOAD_SURVEY_BASE_ADRESS),HEX2DEC(T13))) -> 23E7 | X13: =SUM(X12+0) -> 7 | Y13: =SUM(Y11+1) -> 5 | Z13: =IF(Z12=30,0,30) -> 0 | AA13: =SUM(AA12+1) -> 10 | AB13: =DEC2HEX(SUM((X13*slots_per_day_1phase)+AA13)*numberofbytes_tostore_1phase) -> 38C4 | AC13: =DEC2HEX(SUM(HEX2DEC(LOAD_SURVEY_BASE_ADRESS),HEX2DEC(AB13))) -> 4B47 | AF13: =SUM(AF12+0) -> 21 | AG13: =SUM(AG11+1) -> 5 | AH13: =IF(AH12=30,0,30) -> 0 | AI13: =SUM(AI12+1) -> 10 | AJ13: =DEC2HEX(SUM((AF13*slots_per_day_1phase)+AI13)*numberofbytes_tostore_1phase) -> A704 | AK13: =DEC2HEX(SUM(HEX2DEC(LOAD_SURVEY_BASE_ADRESS),HEX2DEC(AJ13))) -> B987 | AN13: =SUM(AN12+0) -> 34 | AO13: =SUM(AO11+1) -> 5 | AP13: =IF(AP12=30,0,30) -> 0 | AQ13: =SUM(AQ12+1) -> 10 | AR13: =DEC2HEX(SUM((AN13*slots_per_day_1phase)+AQ13)*numberofbytes_tostore_1phase) -> 10D64 | AS13: =DEC2HEX(SUM(HEX2DEC(LOAD_SURVEY_BASE_ADRESS),HEX2DEC(AR13))) -> 11FE7 | AV13: 60 | AW13: =SUM(AW11+1) -> 5 | AX13: =IF(AX12=30,0,30) -> 0 | AY13: =SUM(AY12+1) -> 10 | AZ13: =DEC2HEX(SUM((AV13*slots_per_day_1phase)+AY13)*numberofbytes_tostore_1phase) -> 1DA24 | BA13: =DEC2HEX(SUM(HEX2DEC(LOAD_SURVEY_BASE_ADRESS),HEX2DEC(AZ13))) -> 1ECA7
B14: 0 | C14: =C13 -> 5 | D14: =IF(D13=30,0,30) -> 30 | E14: =SUM(E13+1) -> 11 | F14: =DEC2HEX(SUM((B14*slots_per_day_1phase)+E14)*numberofbytes_tostore_1phase) -> 1CE | G14: =DEC2HEX(SUM(HEX2DEC(LOAD_SURVEY_BASE_ADRESS),HEX2DEC(F14))) -> 1451 | I14: 1 | J14: =J13 -> 5 | K14: =IF(K13=30,0,30) -> 30 | L14: =SUM(L13+1) -> 11 | M14: =DEC2HEX(SUM((I14*slots_per_day_1phase)+L14)*numberofbytes_tostore_1phase) -> 9AE | N14: =DEC2HEX(SUM(HEX2DEC(LOAD_SURVEY_BASE_ADRESS),HEX2DEC(M14))) -> 1C31 | P14: =SUM(P13+0) -> 2 | Q14: =Q13 -> 5 | R14: =IF(R13=30,0,30) -> 30 | S14: =SUM(S13+1) -> 11 | T14: =DEC2HEX(SUM((P14*slots_per_day_1phase)+S14)*numberofbytes_tostore_1phase) -> 118E | U14: =DEC2HEX(SUM(HEX2DEC(LOAD_SURVEY_BASE_ADRESS),HEX2DEC(T14))) -> 2411 | X14: =SUM(X13+0) -> 7 | Y14: =Y13 -> 5 | Z14: =IF(Z13=30,0,30) -> 30 | AA14: =SUM(AA13+1) -> 11 | AB14: =DEC2HEX(SUM((X14*slots_per_day_1phase)+AA14)*numberofbytes_tostore_1phase) -> 38EE | AC14: =DEC2HEX(SUM(HEX2DEC(LOAD_SURVEY_BASE_ADRESS),HEX2DEC(AB14))) -> 4B71 | AF14: =SUM(AF13+0) -> 21 | AG14: =AG13 -> 5 | AH14: =IF(AH13=30,0,30) -> 30 | AI14: =SUM(AI13+1) -> 11 | AJ14: =DEC2HEX(SUM((AF14*slots_per_day_1phase)+AI14)*numberofbytes_tostore_1phase) -> A72E | AK14: =DEC2HEX(SUM(HEX2DEC(LOAD_SURVEY_BASE_ADRESS),HEX2DEC(AJ14))) -> B9B1 | AN14: =SUM(AN13+0) -> 34 | AO14: =AO13 -> 5 | AP14: =IF(AP13=30,0,30) -> 30 | AQ14: =SUM(AQ13+1) -> 11 | AR14: =DEC2HEX(SUM((AN14*slots_per_day_1phase)+AQ14)*numberofbytes_tostore_1phase) -> 10D8E | AS14: =DEC2HEX(SUM(HEX2DEC(LOAD_SURVEY_BASE_ADRESS),HEX2DEC(AR14))) -> 12011 | AV14: 60 | AW14: =AW13 -> 5 | AX14: =IF(AX13=30,0,30) -> 30 | AY14: =SUM(AY13+1) -> 11 | AZ14: =DEC2HEX(SUM((AV14*slots_per_day_1phase)+AY14)*numberofbytes_tostore_1phase) -> 1DA4E | BA14: =DEC2HEX(SUM(HEX2DEC(LOAD_SURVEY_BASE_ADRESS),HEX2DEC(AZ14))) -> 1ECD1
B15: 0 | C15: =SUM(C13+1) -> 6 | D15: =IF(D14=30,0,30) -> 0 | E15: =SUM(E14+1) -> 12 | F15: =DEC2HEX(SUM((B15*slots_per_day_1phase)+E15)*numberofbytes_tostore_1phase) -> 1F8 | G15: =DEC2HEX(SUM(HEX2DEC(LOAD_SURVEY_BASE_ADRESS),HEX2DEC(F15))) -> 147B | I15: 1 | J15: =SUM(J13+1) -> 6 | K15: =IF(K14=30,0,30) -> 0 | L15: =SUM(L14+1) -> 12 | M15: =DEC2HEX(SUM((I15*slots_per_day_1phase)+L15)*numberofbytes_tostore_1phase) -> 9D8 | N15: =DEC2HEX(SUM(HEX2DEC(LOAD_SURVEY_BASE_ADRESS),HEX2DEC(M15))) -> 1C5B | P15: =SUM(P14+0) -> 2 | Q15: =SUM(Q13+1) -> 6 | R15: =IF(R14=30,0,30) -> 0 | S15: =SUM(S14+1) -> 12 | T15: =DEC2HEX(SUM((P15*slots_per_day_1phase)+S15)*numberofbytes_tostore_1phase) -> 11B8 | U15: =DEC2HEX(SUM(HEX2DEC(LOAD_SURVEY_BASE_ADRESS),HEX2DEC(T15))) -> 243B | X15: =SUM(X14+0) -> 7 | Y15: =SUM(Y13+1) -> 6 | Z15: =IF(Z14=30,0,30) -> 0 | AA15: =SUM(AA14+1) -> 12 | AB15: =DEC2HEX(SUM((X15*slots_per_day_1phase)+AA15)*numberofbytes_tostore_1phase) -> 3918 | AC15: =DEC2HEX(SUM(HEX2DEC(LOAD_SURVEY_BASE_ADRESS),HEX2DEC(AB15))) -> 4B9B | AF15: =SUM(AF14+0) -> 21 | AG15: =SUM(AG13+1) -> 6 | AH15: =IF(AH14=30,0,30) -> 0 | AI15: =SUM(AI14+1) -> 12 | AJ15: =DEC2HEX(SUM((AF15*slots_per_day_1phase)+AI15)*numberofbytes_tostore_1phase) -> A758 | AK15: =DEC2HEX(SUM(HEX2DEC(LOAD_SURVEY_BASE_ADRESS),HEX2DEC(AJ15))) -> B9DB | AN15: =SUM(AN14+0) -> 34 | AO15: =SUM(AO13+1) -> 6 | AP15: =IF(AP14=30,0,30) -> 0 | AQ15: =SUM(AQ14+1) -> 12 | AR15: =DEC2HEX(SUM((AN15*slots_per_day_1phase)+AQ15)*numberofbytes_tostore_1phase) -> 10DB8 | AS15: =DEC2HEX(SUM(HEX2DEC(LOAD_SURVEY_BASE_ADRESS),HEX2DEC(AR15))) -> 1203B | AV15: 60 | AW15: =SUM(AW13+1) -> 6 | AX15: =IF(AX14=30,0,30) -> 0 | AY15: =SUM(AY14+1) -> 12 | AZ15: =DEC2HEX(SUM((AV15*slots_per_day_1phase)+AY15)*numberofbytes_tostore_1phase) -> 1DA78 | BA15: =DEC2HEX(SUM(HEX2DEC(LOAD_SURVEY_BASE_ADRESS),HEX2DEC(AZ15))) -> 1ECFB
B16: 0 | C16: =C15 -> 6 | D16: =IF(D15=30,0,30) -> 30 | E16: =SUM(E15+1) -> 13 | F16: =DEC2HEX(SUM((B16*slots_per_day_1phase)+E16)*numberofbytes_tostore_1phase) -> 222 | G16: =DEC2HEX(SUM(HEX2DEC(LOAD_SURVEY_BASE_ADRESS),HEX2DEC(F16))) -> 14A5 | I16: 1 | J16: =J15 -> 6 | K16: =IF(K15=30,0,30) -> 30 | L16: =SUM(L15+1) -> 13 | M16: =DEC2HEX(SUM((I16*slots_per_day_1phase)+L16)*numberofbytes_tostore_1phase) -> A02 | N16: =DEC2HEX(SUM(HEX2DEC(LOAD_SURVEY_BASE_ADRESS),HEX2DEC(M16))) -> 1C85 | P16: =SUM(P15+0) -> 2 | Q16: =Q15 -> 6 | R16: =IF(R15=30,0,30) -> 30 | S16: =SUM(S15+1) -> 13 | T16: =DEC2HEX(SUM((P16*slots_per_day_1phase)+S16)*numberofbytes_tostore_1phase) -> 11E2 | U16: =DEC2HEX(SUM(HEX2DEC(LOAD_SURVEY_BASE_ADRESS),HEX2DEC(T16))) -> 2465 | X16: =SUM(X15+0) -> 7 | Y16: =Y15 -> 6 | Z16: =IF(Z15=30,0,30) -> 30 | AA16: =SUM(AA15+1) -> 13 | AB16: =DEC2HEX(SUM((X16*slots_per_day_1phase)+AA16)*numberofbytes_tostore_1phase) -> 3942 | AC16: =DEC2HEX(SUM(HEX2DEC(LOAD_SURVEY_BASE_ADRESS),HEX2DEC(AB16))) -> 4BC5 | AF16: =SUM(AF15+0) -> 21 | AG16: =AG15 -> 6 | AH16: =IF(AH15=30,0,30) -> 30 | AI16: =SUM(AI15+1) -> 13 | AJ16: =DEC2HEX(SUM((AF16*slots_per_day_1phase)+AI16)*numberofbytes_tostore_1phase) -> A782 | AK16: =DEC2HEX(SUM(HEX2DEC(LOAD_SURVEY_BASE_ADRESS),HEX2DEC(AJ16))) -> BA05 | AN16: =SUM(AN15+0) -> 34 | AO16: =AO15 -> 6 | AP16: =IF(AP15=30,0,30) -> 30 | AQ16: =SUM(AQ15+1) -> 13 | AR16: =DEC2HEX(SUM((AN16*slots_per_day_1phase)+AQ16)*numberofbytes_tostore_1phase) -> 10DE2 | AS16: =DEC2HEX(SUM(HEX2DEC(LOAD_SURVEY_BASE_ADRESS),HEX2DEC(AR16))) -> 12065 | AV16: 60 | AW16: =AW15 -> 6 | AX16: =IF(AX15=30,0,30) -> 30 | AY16: =SUM(AY15+1) -> 13 | AZ16: =DEC2HEX(SUM((AV16*slots_per_day_1phase)+AY16)*numberofbytes_tostore_1phase) -> 1DAA2 | BA16: =DEC2HEX(SUM(HEX2DEC(LOAD_SURVEY_BASE_ADRESS),HEX2DEC(AZ16))) -> 1ED25
B17: 0 | C17: =SUM(C15+1) -> 7 | D17: =IF(D16=30,0,30) -> 0 | E17: =SUM(E16+1) -> 14 | F17: =DEC2HEX(SUM((B17*slots_per_day_1phase)+E17)*numberofbytes_tostore_1phase) -> 24C | G17: =DEC2HEX(SUM(HEX2DEC(LOAD_SURVEY_BASE_ADRESS),HEX2DEC(F17))) -> 14CF | I17: 1 | J17: =SUM(J15+1) -> 7 | K17: =IF(K16=30,0,30) -> 0 | L17: =SUM(L16+1) -> 14 | M17: =DEC2HEX(SUM((I17*slots_per_day_1phase)+L17)*numberofbytes_tostore_1phase) -> A2C | N17: =DEC2HEX(SUM(HEX2DEC(LOAD_SURVEY_BASE_ADRESS),HEX2DEC(M17))) -> 1CAF | P17: =SUM(P16+0) -> 2 | Q17: =SUM(Q15+1) -> 7 | R17: =IF(R16=30,0,30) -> 0 | S17: =SUM(S16+1) -> 14 | T17: =DEC2HEX(SUM((P17*slots_per_day_1phase)+S17)*numberofbytes_tostore_1phase) -> 120C | U17: =DEC2HEX(SUM(HEX2DEC(LOAD_SURVEY_BASE_ADRESS),HEX2DEC(T17))) -> 248F | X17: =SUM(X16+0) -> 7 | Y17: =SUM(Y15+1) -> 7 | Z17: =IF(Z16=30,0,30) -> 0 | AA17: =SUM(AA16+1) -> 14 | AB17: =DEC2HEX(SUM((X17*slots_per_day_1phase)+AA17)*numberofbytes_tostore_1phase) -> 396C | AC17: =DEC2HEX(SUM(HEX2DEC(LOAD_SURVEY_BASE_ADRESS),HEX2DEC(AB17))) -> 4BEF | AF17: =SUM(AF16+0) -> 21 | AG17: =SUM(AG15+1) -> 7 | AH17: =IF(AH16=30,0,30) -> 0 | AI17: =SUM(AI16+1) -> 14 | AJ17: =DEC2HEX(SUM((AF17*slots_per_day_1phase)+AI17)*numberofbytes_tostore_1phase) -> A7AC | AK17: =DEC2HEX(SUM(HEX2DEC(LOAD_SURVEY_BASE_ADRESS),HEX2DEC(AJ17))) -> BA2F | AN17: =SUM(AN16+0) -> 34 | AO17: =SUM(AO15+1) -> 7 | AP17: =IF(AP16=30,0,30) -> 0 | AQ17: =SUM(AQ16+1) -> 14 | AR17: =DEC2HEX(SUM((AN17*slots_per_day_1phase)+AQ17)*numberofbytes_tostore_1phase) -> 10E0C | AS17: =DEC2HEX(SUM(HEX2DEC(LOAD_SURVEY_BASE_ADRESS),HEX2DEC(AR17))) -> 1208F | AV17: 60 | AW17: =SUM(AW15+1) -> 7 | AX17: =IF(AX16=30,0,30) -> 0 | AY17: =SUM(AY16+1) -> 14 | AZ17: =DEC2HEX(SUM((AV17*slots_per_day_1phase)+AY17)*numberofbytes_tostore_1phase) -> 1DACC | BA17: =DEC2HEX(SUM(HEX2DEC(LOAD_SURVEY_BASE_ADRESS),HEX2DEC(AZ17))) -> 1ED4F
B18: 0 | C18: =C17 -> 7 | D18: =IF(D17=30,0,30) -> 30 | E18: =SUM(E17+1) -> 15 | F18: =DEC2HEX(SUM((B18*slots_per_day_1phase)+E18)*numberofbytes_tostore_1phase) -> 276 | G18: =DEC2HEX(SUM(HEX2DEC(LOAD_SURVEY_BASE_ADRESS),HEX2DEC(F18))) -> 14F9 | I18: 1 | J18: =J17 -> 7 | K18: =IF(K17=30,0,30) -> 30 | L18: =SUM(L17+1) -> 15 | M18: =DEC2HEX(SUM((I18*slots_per_day_1phase)+L18)*numberofbytes_tostore_1phase) -> A56 | N18: =DEC2HEX(SUM(HEX2DEC(LOAD_SURVEY_BASE_ADRESS),HEX2DEC(M18))) -> 1CD9 | P18: =SUM(P17+0) -> 2 | Q18: =Q17 -> 7 | R18: =IF(R17=30,0,30) -> 30 | S18: =SUM(S17+1) -> 15 | T18: =DEC2HEX(SUM((P18*slots_per_day_1phase)+S18)*numberofbytes_tostore_1phase) -> 1236 | U18: =DEC2HEX(SUM(HEX2DEC(LOAD_SURVEY_BASE_ADRESS),HEX2DEC(T18))) -> 24B9 | X18: =SUM(X17+0) -> 7 | Y18: =Y17 -> 7 | Z18: =IF(Z17=30,0,30) -> 30 | AA18: =SUM(AA17+1) -> 15 | AB18: =DEC2HEX(SUM((X18*slots_per_day_1phase)+AA18)*numberofbytes_tostore_1phase) -> 3996 | AC18: =DEC2HEX(SUM(HEX2DEC(LOAD_SURVEY_BASE_ADRESS),HEX2DEC(AB18))) -> 4C19 | AF18: =SUM(AF17+0) -> 21 | AG18: =AG17 -> 7 | AH18: =IF(AH17=30,0,30) -> 30 | AI18: =SUM(AI17+1) -> 15 | AJ18: =DEC2HEX(SUM((AF18*slots_per_day_1phase)+AI18)*numberofbytes_tostore_1phase) -> A7D6 | AK18: =DEC2HEX(SUM(HEX2DEC(LOAD_SURVEY_BASE_ADRESS),HEX2DEC(AJ18))) -> BA59 | AN18: =SUM(AN17+0) -> 34 | AO18: =AO17 -> 7 | AP18: =IF(AP17=30,0,30) -> 30 | AQ18: =SUM(AQ17+1) -> 15 | AR18: =DEC2HEX(SUM((AN18*slots_per_day_1phase)+AQ18)*numberofbytes_tostore_1phase) -> 10E36 | AS18: =DEC2HEX(SUM(HEX2DEC(LOAD_SURVEY_BASE_ADRESS),HEX2DEC(AR18))) -> 120B9 | AV18: 60 | AW18: =AW17 -> 7 | AX18: =IF(AX17=30,0,30) -> 30 | AY18: =SUM(AY17+1) -> 15 | AZ18: =DEC2HEX(SUM((AV18*slots_per_day_1phase)+AY18)*numberofbytes_tostore_1phase) -> 1DAF6 | BA18: =DEC2HEX(SUM(HEX2DEC(LOAD_SURVEY_BASE_ADRESS),HEX2DEC(AZ18))) -> 1ED79
B19: 0 | C19: =SUM(C17+1) -> 8 | D19: =IF(D18=30,0,30) -> 0 | E19: =SUM(E18+1) -> 16 | F19: =DEC2HEX(SUM((B19*slots_per_day_1phase)+E19)*numberofbytes_tostore_1phase) -> 2A0 | G19: =DEC2HEX(SUM(HEX2DEC(LOAD_SURVEY_BASE_ADRESS),HEX2DEC(F19))) -> 1523 | I19: 1 | J19: =SUM(J17+1) -> 8 | K19: =IF(K18=30,0,30) -> 0 | L19: =SUM(L18+1) -> 16 | M19: =DEC2HEX(SUM((I19*slots_per_day_1phase)+L19)*numberofbytes_tostore_1phase) -> A80 | N19: =DEC2HEX(SUM(HEX2DEC(LOAD_SURVEY_BASE_ADRESS),HEX2DEC(M19))) -> 1D03 | P19: =SUM(P18+0) -> 2 | Q19: =SUM(Q17+1) -> 8 | R19: =IF(R18=30,0,30) -> 0 | S19: =SUM(S18+1) -> 16 | T19: =DEC2HEX(SUM((P19*slots_per_day_1phase)+S19)*numberofbytes_tostore_1phase) -> 1260 | U19: =DEC2HEX(SUM(HEX2DEC(LOAD_SURVEY_BASE_ADRESS),HEX2DEC(T19))) -> 24E3 | X19: =SUM(X18+0) -> 7 | Y19: =SUM(Y17+1) -> 8 | Z19: =IF(Z18=30,0,30) -> 0 | AA19: =SUM(AA18+1) -> 16 | AB19: =DEC2HEX(SUM((X19*slots_per_day_1phase)+AA19)*numberofbytes_tostore_1phase) -> 39C0 | AC19: =DEC2HEX(SUM(HEX2DEC(LOAD_SURVEY_BASE_ADRESS),HEX2DEC(AB19))) -> 4C43 | AF19: =SUM(AF18+0) -> 21 | AG19: =SUM(AG17+1) -> 8 | AH19: =IF(AH18=30,0,30) -> 0 | AI19: =SUM(AI18+1) -> 16 | AJ19: =DEC2HEX(SUM((AF19*slots_per_day_1phase)+AI19)*numberofbytes_tostore_1phase) -> A800 | AK19: =DEC2HEX(SUM(HEX2DEC(LOAD_SURVEY_BASE_ADRESS),HEX2DEC(AJ19))) -> BA83 | AN19: =SUM(AN18+0) -> 34 | AO19: =SUM(AO17+1) -> 8 | AP19: =IF(AP18=30,0,30) -> 0 | AQ19: =SUM(AQ18+1) -> 16 | AR19: =DEC2HEX(SUM((AN19*slots_per_day_1phase)+AQ19)*numberofbytes_tostore_1phase) -> 10E60 | AS19: =DEC2HEX(SUM(HEX2DEC(LOAD_SURVEY_BASE_ADRESS),HEX2DEC(AR19))) -> 120E3 | AV19: 60 | AW19: =SUM(AW17+1) -> 8 | AX19: =IF(AX18=30,0,30) -> 0 | AY19: =SUM(AY18+1) -> 16 | AZ19: =DEC2HEX(SUM((AV19*slots_per_day_1phase)+AY19)*numberofbytes_tostore_1phase) -> 1DB20 | BA19: =DEC2HEX(SUM(HEX2DEC(LOAD_SURVEY_BASE_ADRESS),HEX2DEC(AZ19))) -> 1EDA3
B20: 0 | C20: =C19 -> 8 | D20: =IF(D19=30,0,30) -> 30 | E20: =SUM(E19+1) -> 17 | F20: =DEC2HEX(SUM((B20*slots_per_day_1phase)+E20)*numberofbytes_tostore_1phase) -> 2CA | G20: =DEC2HEX(SUM(HEX2DEC(LOAD_SURVEY_BASE_ADRESS),HEX2DEC(F20))) -> 154D | I20: 1 | J20: =J19 -> 8 | K20: =IF(K19=30,0,30) -> 30 | L20: =SUM(L19+1) -> 17 | M20: =DEC2HEX(SUM((I20*slots_per_day_1phase)+L20)*numberofbytes_tostore_1phase) -> AAA | N20: =DEC2HEX(SUM(HEX2DEC(LOAD_SURVEY_BASE_ADRESS),HEX2DEC(M20))) -> 1D2D | P20: =SUM(P19+0) -> 2 | Q20: =Q19 -> 8 | R20: =IF(R19=30,0,30) -> 30 | S20: =SUM(S19+1) -> 17 | T20: =DEC2HEX(SUM((P20*slots_per_day_1phase)+S20)*numberofbytes_tostore_1phase) -> 128A | U20: =DEC2HEX(SUM(HEX2DEC(LOAD_SURVEY_BASE_ADRESS),HEX2DEC(T20))) -> 250D | X20: =SUM(X19+0) -> 7 | Y20: =Y19 -> 8 | Z20: =IF(Z19=30,0,30) -> 30 | AA20: =SUM(AA19+1) -> 17 | AB20: =DEC2HEX(SUM((X20*slots_per_day_1phase)+AA20)*numberofbytes_tostore_1phase) -> 39EA | AC20: =DEC2HEX(SUM(HEX2DEC(LOAD_SURVEY_BASE_ADRESS),HEX2DEC(AB20))) -> 4C6D | AF20: =SUM(AF19+0) -> 21 | AG20: =AG19 -> 8 | AH20: =IF(AH19=30,0,30) -> 30 | AI20: =SUM(AI19+1) -> 17 | AJ20: =DEC2HEX(SUM((AF20*slots_per_day_1phase)+AI20)*numberofbytes_tostore_1phase) -> A82A | AK20: =DEC2HEX(SUM(HEX2DEC(LOAD_SURVEY_BASE_ADRESS),HEX2DEC(AJ20))) -> BAAD | AN20: =SUM(AN19+0) -> 34 | AO20: =AO19 -> 8 | AP20: =IF(AP19=30,0,30) -> 30 | AQ20: =SUM(AQ19+1) -> 17 | AR20: =DEC2HEX(SUM((AN20*slots_per_day_1phase)+AQ20)*numberofbytes_tostore_1phase) -> 10E8A | AS20: =DEC2HEX(SUM(HEX2DEC(LOAD_SURVEY_BASE_ADRESS),HEX2DEC(AR20))) -> 1210D | AV20: 60 | AW20: =AW19 -> 8 | AX20: =IF(AX19=30,0,30) -> 30 | AY20: =SUM(AY19+1) -> 17 | AZ20: =DEC2HEX(SUM((AV20*slots_per_day_1phase)+AY20)*numberofbytes_tostore_1phase) -> 1DB4A | BA20: =DEC2HEX(SUM(HEX2DEC(LOAD_SURVEY_BASE_ADRESS),HEX2DEC(AZ20))) -> 1EDCD
B21: 0 | C21: =SUM(C19+1) -> 9 | D21: =IF(D20=30,0,30) -> 0 | E21: =SUM(E20+1) -> 18 | F21: =DEC2HEX(SUM((B21*slots_per_day_1phase)+E21)*numberofbytes_tostore_1phase) -> 2F4 | G21: =DEC2HEX(SUM(HEX2DEC(LOAD_SURVEY_BASE_ADRESS),HEX2DEC(F21))) -> 1577 | I21: 1 | J21: =SUM(J19+1) -> 9 | K21: =IF(K20=30,0,30) -> 0 | L21: =SUM(L20+1) -> 18 | M21: =DEC2HEX(SUM((I21*slots_per_day_1phase)+L21)*numberofbytes_tostore_1phase) -> AD4 | N21: =DEC2HEX(SUM(HEX2DEC(LOAD_SURVEY_BASE_ADRESS),HEX2DEC(M21))) -> 1D57 | P21: =SUM(P20+0) -> 2 | Q21: =SUM(Q19+1) -> 9 | R21: =IF(R20=30,0,30) -> 0 | S21: =SUM(S20+1) -> 18 | T21: =DEC2HEX(SUM((P21*slots_per_day_1phase)+S21)*numberofbytes_tostore_1phase) -> 12B4 | U21: =DEC2HEX(SUM(HEX2DEC(LOAD_SURVEY_BASE_ADRESS),HEX2DEC(T21))) -> 2537 | X21: =SUM(X20+0) -> 7 | Y21: =SUM(Y19+1) -> 9 | Z21: =IF(Z20=30,0,30) -> 0 | AA21: =SUM(AA20+1) -> 18 | AB21: =DEC2HEX(SUM((X21*slots_per_day_1phase)+AA21)*numberofbytes_tostore_1phase) -> 3A14 | AC21: =DEC2HEX(SUM(HEX2DEC(LOAD_SURVEY_BASE_ADRESS),HEX2DEC(AB21))) -> 4C97 | AF21: =SUM(AF20+0) -> 21 | AG21: =SUM(AG19+1) -> 9 | AH21: =IF(AH20=30,0,30) -> 0 | AI21: =SUM(AI20+1) -> 18 | AJ21: =DEC2HEX(SUM((AF21*slots_per_day_1phase)+AI21)*numberofbytes_tostore_1phase) -> A854 | AK21: =DEC2HEX(SUM(HEX2DEC(LOAD_SURVEY_BASE_ADRESS),HEX2DEC(AJ21))) -> BAD7 | AN21: =SUM(AN20+0) -> 34 | AO21: =SUM(AO19+1) -> 9 | AP21: =IF(AP20=30,0,30) -> 0 | AQ21: =SUM(AQ20+1) -> 18 | AR21: =DEC2HEX(SUM((AN21*slots_per_day_1phase)+AQ21)*numberofbytes_tostore_1phase) -> 10EB4 | AS21: =DEC2HEX(SUM(HEX2DEC(LOAD_SURVEY_BASE_ADRESS),HEX2DEC(AR21))) -> 12137 | AV21: 60 | AW21: =SUM(AW19+1) -> 9 | AX21: =IF(AX20=30,0,30) -> 0 | AY21: =SUM(AY20+1) -> 18 | AZ21: =DEC2HEX(SUM((AV21*slots_per_day_1phase)+AY21)*numberofbytes_tostore_1phase) -> 1DB74 | BA21: =DEC2HEX(SUM(HEX2DEC(LOAD_SURVEY_BASE_ADRESS),HEX2DEC(AZ21))) -> 1EDF7
B22: 0 | C22: =C21 -> 9 | D22: =IF(D21=30,0,30) -> 30 | E22: =SUM(E21+1) -> 19 | F22: =DEC2HEX(SUM((B22*slots_per_day_1phase)+E22)*numberofbytes_tostore_1phase) -> 31E | G22: =DEC2HEX(SUM(HEX2DEC(LOAD_SURVEY_BASE_ADRESS),HEX2DEC(F22))) -> 15A1 | I22: 1 | J22: =J21 -> 9 | K22: =IF(K21=30,0,30) -> 30 | L22: =SUM(L21+1) -> 19 | M22: =DEC2HEX(SUM((I22*slots_per_day_1phase)+L22)*numberofbytes_tostore_1phase) -> AFE | N22: =DEC2HEX(SUM(HEX2DEC(LOAD_SURVEY_BASE_ADRESS),HEX2DEC(M22))) -> 1D81 | P22: =SUM(P21+0) -> 2 | Q22: =Q21 -> 9 | R22: =IF(R21=30,0,30) -> 30 | S22: =SUM(S21+1) -> 19 | T22: =DEC2HEX(SUM((P22*slots_per_day_1phase)+S22)*numberofbytes_tostore_1phase) -> 12DE | U22: =DEC2HEX(SUM(HEX2DEC(LOAD_SURVEY_BASE_ADRESS),HEX2DEC(T22))) -> 2561 | X22: =SUM(X21+0) -> 7 | Y22: =Y21 -> 9 | Z22: =IF(Z21=30,0,30) -> 30 | AA22: =SUM(AA21+1) -> 19 | AB22: =DEC2HEX(SUM((X22*slots_per_day_1phase)+AA22)*numberofbytes_tostore_1phase) -> 3A3E | AC22: =DEC2HEX(SUM(HEX2DEC(LOAD_SURVEY_BASE_ADRESS),HEX2DEC(AB22))) -> 4CC1 | AF22: =SUM(AF21+0) -> 21 | AG22: =AG21 -> 9 | AH22: =IF(AH21=30,0,30) -> 30 | AI22: =SUM(AI21+1) -> 19 | AJ22: =DEC2HEX(SUM((AF22*slots_per_day_1phase)+AI22)*numberofbytes_tostore_1phase) -> A87E | AK22: =DEC2HEX(SUM(HEX2DEC(LOAD_SURVEY_BASE_ADRESS),HEX2DEC(AJ22))) -> BB01 | AN22: =SUM(AN21+0) -> 34 | AO22: =AO21 -> 9 | AP22: =IF(AP21=30,0,30) -> 30 | AQ22: =SUM(AQ21+1) -> 19 | AR22: =DEC2HEX(SUM((AN22*slots_per_day_1phase)+AQ22)*numberofbytes_tostore_1phase) -> 10EDE | AS22: =DEC2HEX(SUM(HEX2DEC(LOAD_SURVEY_BASE_ADRESS),HEX2DEC(AR22))) -> 12161 | AV22: 60 | AW22: =AW21 -> 9 | AX22: =IF(AX21=30,0,30) -> 30 | AY22: =SUM(AY21+1) -> 19 | AZ22: =DEC2HEX(SUM((AV22*slots_per_day_1phase)+AY22)*numberofbytes_tostore_1phase) -> 1DB9E | BA22: =DEC2HEX(SUM(HEX2DEC(LOAD_SURVEY_BASE_ADRESS),HEX2DEC(AZ22))) -> 1EE21
B23: 0 | C23: =SUM(C21+1) -> 10 | D23: =IF(D22=30,0,30) -> 0 | E23: =SUM(E22+1) -> 20 | F23: =DEC2HEX(SUM((B23*slots_per_day_1phase)+E23)*numberofbytes_tostore_1phase) -> 348 | G23: =DEC2HEX(SUM(HEX2DEC(LOAD_SURVEY_BASE_ADRESS),HEX2DEC(F23))) -> 15CB | I23: 1 | J23: =SUM(J21+1) -> 10 | K23: =IF(K22=30,0,30) -> 0 | L23: =SUM(L22+1) -> 20 | M23: =DEC2HEX(SUM((I23*slots_per_day_1phase)+L23)*numberofbytes_tostore_1phase) -> B28 | N23: =DEC2HEX(SUM(HEX2DEC(LOAD_SURVEY_BASE_ADRESS),HEX2DEC(M23))) -> 1DAB | P23: =SUM(P22+0) -> 2 | Q23: =SUM(Q21+1) -> 10 | R23: =IF(R22=30,0,30) -> 0 | S23: =SUM(S22+1) -> 20 | T23: =DEC2HEX(SUM((P23*slots_per_day_1phase)+S23)*numberofbytes_tostore_1phase) -> 1308 | U23: =DEC2HEX(SUM(HEX2DEC(LOAD_SURVEY_BASE_ADRESS),HEX2DEC(T23))) -> 258B | X23: =SUM(X22+0) -> 7 | Y23: =SUM(Y21+1) -> 10 | Z23: =IF(Z22=30,0,30) -> 0 | AA23: =SUM(AA22+1) -> 20 | AB23: =DEC2HEX(SUM((X23*slots_per_day_1phase)+AA23)*numberofbytes_tostore_1phase) -> 3A68 | AC23: =DEC2HEX(SUM(HEX2DEC(LOAD_SURVEY_BASE_ADRESS),HEX2DEC(AB23))) -> 4CEB | AF23: =SUM(AF22+0) -> 21 | AG23: =SUM(AG21+1) -> 10 | AH23: =IF(AH22=30,0,30) -> 0 | AI23: =SUM(AI22+1) -> 20 | AJ23: =DEC2HEX(SUM((AF23*slots_per_day_1phase)+AI23)*numberofbytes_tostore_1phase) -> A8A8 | AK23: =DEC2HEX(SUM(HEX2DEC(LOAD_SURVEY_BASE_ADRESS),HEX2DEC(AJ23))) -> BB2B | AN23: =SUM(AN22+0) -> 34 | AO23: =SUM(AO21+1) -> 10 | AP23: =IF(AP22=30,0,30) -> 0 | AQ23: =SUM(AQ22+1) -> 20 | AR23: =DEC2HEX(SUM((AN23*slots_per_day_1phase)+AQ23)*numberofbytes_tostore_1phase) -> 10F08 | AS23: =DEC2HEX(SUM(HEX2DEC(LOAD_SURVEY_BASE_ADRESS),HEX2DEC(AR23))) -> 1218B | AV23: 60 | AW23: =SUM(AW21+1) -> 10 | AX23: =IF(AX22=30,0,30) -> 0 | AY23: =SUM(AY22+1) -> 20 | AZ23: =DEC2HEX(SUM((AV23*slots_per_day_1phase)+AY23)*numberofbytes_tostore_1phase) -> 1DBC8 | BA23: =DEC2HEX(SUM(HEX2DEC(LOAD_SURVEY_BASE_ADRESS),HEX2DEC(AZ23))) -> 1EE4B
B24: 0 | C24: =C23 -> 10 | D24: =IF(D23=30,0,30) -> 30 | E24: =SUM(E23+1) -> 21 | F24: =DEC2HEX(SUM((B24*slots_per_day_1phase)+E24)*numberofbytes_tostore_1phase) -> 372 | G24: =DEC2HEX(SUM(HEX2DEC(LOAD_SURVEY_BASE_ADRESS),HEX2DEC(F24))) -> 15F5 | I24: 1 | J24: =J23 -> 10 | K24: =IF(K23=30,0,30) -> 30 | L24: =SUM(L23+1) -> 21 | M24: =DEC2HEX(SUM((I24*slots_per_day_1phase)+L24)*numberofbytes_tostore_1phase) -> B52 | N24: =DEC2HEX(SUM(HEX2DEC(LOAD_SURVEY_BASE_ADRESS),HEX2DEC(M24))) -> 1DD5 | P24: =SUM(P23+0) -> 2 | Q24: =Q23 -> 10 | R24: =IF(R23=30,0,30) -> 30 | S24: =SUM(S23+1) -> 21 | T24: =DEC2HEX(SUM((P24*slots_per_day_1phase)+S24)*numberofbytes_tostore_1phase) -> 1332 | U24: =DEC2HEX(SUM(HEX2DEC(LOAD_SURVEY_BASE_ADRESS),HEX2DEC(T24))) -> 25B5 | X24: =SUM(X23+0) -> 7 | Y24: =Y23 -> 10 | Z24: =IF(Z23=30,0,30) -> 30 | AA24: =SUM(AA23+1) -> 21 | AB24: =DEC2HEX(SUM((X24*slots_per_day_1phase)+AA24)*numberofbytes_tostore_1phase) -> 3A92 | AC24: =DEC2HEX(SUM(HEX2DEC(LOAD_SURVEY_BASE_ADRESS),HEX2DEC(AB24))) -> 4D15 | AF24: =SUM(AF23+0) -> 21 | AG24: =AG23 -> 10 | AH24: =IF(AH23=30,0,30) -> 30 | AI24: =SUM(AI23+1) -> 21 | AJ24: =DEC2HEX(SUM((AF24*slots_per_day_1phase)+AI24)*numberofbytes_tostore_1phase) -> A8D2 | AK24: =DEC2HEX(SUM(HEX2DEC(LOAD_SURVEY_BASE_ADRESS),HEX2DEC(AJ24))) -> BB55 | AN24: =SUM(AN23+0) -> 34 | AO24: =AO23 -> 10 | AP24: =IF(AP23=30,0,30) -> 30 | AQ24: =SUM(AQ23+1) -> 21 | AR24: =DEC2HEX(SUM((AN24*slots_per_day_1phase)+AQ24)*numberofbytes_tostore_1phase) -> 10F32 | AS24: =DEC2HEX(SUM(HEX2DEC(LOAD_SURVEY_BASE_ADRESS),HEX2DEC(AR24))) -> 121B5 | AV24: =SUM(AV23+0) -> 60 | AW24: =AW23 -> 10 | AX24: =IF(AX23=30,0,30) -> 30 | AY24: =SUM(AY23+1) -> 21 | AZ24: =DEC2HEX(SUM((AV24*slots_per_day_1phase)+AY24)*numberofbytes_tostore_1phase) -> 1DBF2 | BA24: =DEC2HEX(SUM(HEX2DEC(LOAD_SURVEY_BASE_ADRESS),HEX2DEC(AZ24))) -> 1EE75
B25: 0 | C25: =SUM(C23+1) -> 11 | D25: =IF(D24=30,0,30) -> 0 | E25: =SUM(E24+1) -> 22 | F25: =DEC2HEX(SUM((B25*slots_per_day_1phase)+E25)*numberofbytes_tostore_1phase) -> 39C | G25: =DEC2HEX(SUM(HEX2DEC(LOAD_SURVEY_BASE_ADRESS),HEX2DEC(F25))) -> 161F | I25: 1 | J25: =SUM(J23+1) -> 11 | K25: =IF(K24=30,0,30) -> 0 | L25: =SUM(L24+1) -> 22 | M25: =DEC2HEX(SUM((I25*slots_per_day_1phase)+L25)*numberofbytes_tostore_1phase) -> B7C | N25: =DEC2HEX(SUM(HEX2DEC(LOAD_SURVEY_BASE_ADRESS),HEX2DEC(M25))) -> 1DFF | P25: =SUM(P24+0) -> 2 | Q25: =SUM(Q23+1) -> 11 | R25: =IF(R24=30,0,30) -> 0 | S25: =SUM(S24+1) -> 22 | T25: =DEC2HEX(SUM((P25*slots_per_day_1phase)+S25)*numberofbytes_tostore_1phase) -> 135C | U25: =DEC2HEX(SUM(HEX2DEC(LOAD_SURVEY_BASE_ADRESS),HEX2DEC(T25))) -> 25DF | X25: =SUM(X24+0) -> 7 | Y25: =SUM(Y23+1) -> 11 | Z25: =IF(Z24=30,0,30) -> 0 | AA25: =SUM(AA24+1) -> 22 | AB25: =DEC2HEX(SUM((X25*slots_per_day_1phase)+AA25)*numberofbytes_tostore_1phase) -> 3ABC | AC25: =DEC2HEX(SUM(HEX2DEC(LOAD_SURVEY_BASE_ADRESS),HEX2DEC(AB25))) -> 4D3F | AF25: =SUM(AF24+0) -> 21 | AG25: =SUM(AG23+1) -> 11 | AH25: =IF(AH24=30,0,30) -> 0 | AI25: =SUM(AI24+1) -> 22 | AJ25: =DEC2HEX(SUM((AF25*slots_per_day_1phase)+AI25)*numberofbytes_tostore_1phase) -> A8FC | AK25: =DEC2HEX(SUM(HEX2DEC(LOAD_SURVEY_BASE_ADRESS),HEX2DEC(AJ25))) -> BB7F | AN25: =SUM(AN24+0) -> 34 | AO25: =SUM(AO23+1) -> 11 | AP25: =IF(AP24=30,0,30) -> 0 | AQ25: =SUM(AQ24+1) -> 22 | AR25: =DEC2HEX(SUM((AN25*slots_per_day_1phase)+AQ25)*numberofbytes_tostore_1phase) -> 10F5C | AS25: =DEC2HEX(SUM(HEX2DEC(LOAD_SURVEY_BASE_ADRESS),HEX2DEC(AR25))) -> 121DF | AV25: =SUM(AV24+0) -> 60 | AW25: =SUM(AW23+1) -> 11 | AX25: =IF(AX24=30,0,30) -> 0 | AY25: =SUM(AY24+1) -> 22 | AZ25: =DEC2HEX(SUM((AV25*slots_per_day_1phase)+AY25)*numberofbytes_tostore_1phase) -> 1DC1C | BA25: =DEC2HEX(SUM(HEX2DEC(LOAD_SURVEY_BASE_ADRESS),HEX2DEC(AZ25))) -> 1EE9F
B26: 0 | C26: =C25 -> 11 | D26: =IF(D25=30,0,30) -> 30 | E26: =SUM(E25+1) -> 23 | F26: =DEC2HEX(SUM((B26*slots_per_day_1phase)+E26)*numberofbytes_tostore_1phase) -> 3C6 | G26: =DEC2HEX(SUM(HEX2DEC(LOAD_SURVEY_BASE_ADRESS),HEX2DEC(F26))) -> 1649 | I26: 1 | J26: =J25 -> 11 | K26: =IF(K25=30,0,30) -> 30 | L26: =SUM(L25+1) -> 23 | M26: =DEC2HEX(SUM((I26*slots_per_day_1phase)+L26)*numberofbytes_tostore_1phase) -> BA6 | N26: =DEC2HEX(SUM(HEX2DEC(LOAD_SURVEY_BASE_ADRESS),HEX2DEC(M26))) -> 1E29 | P26: =SUM(P25+0) -> 2 | Q26: =Q25 -> 11 | R26: =IF(R25=30,0,30) -> 30 | S26: =SUM(S25+1) -> 23 | T26: =DEC2HEX(SUM((P26*slots_per_day_1phase)+S26)*numberofbytes_tostore_1phase) -> 1386 | U26: =DEC2HEX(SUM(HEX2DEC(LOAD_SURVEY_BASE_ADRESS),HEX2DEC(T26))) -> 2609 | X26: =SUM(X25+0) -> 7 | Y26: =Y25 -> 11 | Z26: =IF(Z25=30,0,30) -> 30 | AA26: =SUM(AA25+1) -> 23 | AB26: =DEC2HEX(SUM((X26*slots_per_day_1phase)+AA26)*numberofbytes_tostore_1phase) -> 3AE6 | AC26: =DEC2HEX(SUM(HEX2DEC(LOAD_SURVEY_BASE_ADRESS),HEX2DEC(AB26))) -> 4D69 | AF26: =SUM(AF25+0) -> 21 | AG26: =AG25 -> 11 | AH26: =IF(AH25=30,0,30) -> 30 | AI26: =SUM(AI25+1) -> 23 | AJ26: =DEC2HEX(SUM((AF26*slots_per_day_1phase)+AI26)*numberofbytes_tostore_1phase) -> A926 | AK26: =DEC2HEX(SUM(HEX2DEC(LOAD_SURVEY_BASE_ADRESS),HEX2DEC(AJ26))) -> BBA9 | AN26: =SUM(AN25+0) -> 34 | AO26: =AO25 -> 11 | AP26: =IF(AP25=30,0,30) -> 30 | AQ26: =SUM(AQ25+1) -> 23 | AR26: =DEC2HEX(SUM((AN26*slots_per_day_1phase)+AQ26)*numberofbytes_tostore_1phase) -> 10F86 | AS26: =DEC2HEX(SUM(HEX2DEC(LOAD_SURVEY_BASE_ADRESS),HEX2DEC(AR26))) -> 12209 | AV26: =SUM(AV25+0) -> 60 | AW26: =AW25 -> 11 | AX26: =IF(AX25=30,0,30) -> 30 | AY26: =SUM(AY25+1) -> 23 | AZ26: =DEC2HEX(SUM((AV26*slots_per_day_1phase)+AY26)*numberofbytes_tostore_1phase) -> 1DC46 | BA26: =DEC2HEX(SUM(HEX2DEC(LOAD_SURVEY_BASE_ADRESS),HEX2DEC(AZ26))) -> 1EEC9
B27: 0 | C27: =SUM(C25+1) -> 12 | D27: =IF(D26=30,0,30) -> 0 | E27: =SUM(E26+1) -> 24 | F27: =DEC2HEX(SUM((B27*slots_per_day_1phase)+E27)*numberofbytes_tostore_1phase) -> 3F0 | G27: =DEC2HEX(SUM(HEX2DEC(LOAD_SURVEY_BASE_ADRESS),HEX2DEC(F27))) -> 1673 | I27: 1 | J27: =SUM(J25+1) -> 12 | K27: =IF(K26=30,0,30) -> 0 | L27: =SUM(L26+1) -> 24 | M27: =DEC2HEX(SUM((I27*slots_per_day_1phase)+L27)*numberofbytes_tostore_1phase) -> BD0 | N27: =DEC2HEX(SUM(HEX2DEC(LOAD_SURVEY_BASE_ADRESS),HEX2DEC(M27))) -> 1E53 | P27: =SUM(P26+0) -> 2 | Q27: =SUM(Q25+1) -> 12 | R27: =IF(R26=30,0,30) -> 0 | S27: =SUM(S26+1) -> 24 | T27: =DEC2HEX(SUM((P27*slots_per_day_1phase)+S27)*numberofbytes_tostore_1phase) -> 13B0 | U27: =DEC2HEX(SUM(HEX2DEC(LOAD_SURVEY_BASE_ADRESS),HEX2DEC(T27))) -> 2633 | X27: =SUM(X26+0) -> 7 | Y27: =SUM(Y25+1) -> 12 | Z27: =IF(Z26=30,0,30) -> 0 | AA27: =SUM(AA26+1) -> 24 | AB27: =DEC2HEX(SUM((X27*slots_per_day_1phase)+AA27)*numberofbytes_tostore_1phase) -> 3B10 | AC27: =DEC2HEX(SUM(HEX2DEC(LOAD_SURVEY_BASE_ADRESS),HEX2DEC(AB27))) -> 4D93 | AF27: =SUM(AF26+0) -> 21 | AG27: =SUM(AG25+1) -> 12 | AH27: =IF(AH26=30,0,30) -> 0 | AI27: =SUM(AI26+1) -> 24 | AJ27: =DEC2HEX(SUM((AF27*slots_per_day_1phase)+AI27)*numberofbytes_tostore_1phase) -> A950 | AK27: =DEC2HEX(SUM(HEX2DEC(LOAD_SURVEY_BASE_ADRESS),HEX2DEC(AJ27))) -> BBD3 | AN27: =SUM(AN26+0) -> 34 | AO27: =SUM(AO25+1) -> 12 | AP27: =IF(AP26=30,0,30) -> 0 | AQ27: =SUM(AQ26+1) -> 24 | AR27: =DEC2HEX(SUM((AN27*slots_per_day_1phase)+AQ27)*numberofbytes_tostore_1phase) -> 10FB0 | AS27: =DEC2HEX(SUM(HEX2DEC(LOAD_SURVEY_BASE_ADRESS),HEX2DEC(AR27))) -> 12233 | AV27: =SUM(AV26+0) -> 60 | AW27: =SUM(AW25+1) -> 12 | AX27: =IF(AX26=30,0,30) -> 0 | AY27: =SUM(AY26+1) -> 24 | AZ27: =DEC2HEX(SUM((AV27*slots_per_day_1phase)+AY27)*numberofbytes_tostore_1phase) -> 1DC70 | BA27: =DEC2HEX(SUM(HEX2DEC(LOAD_SURVEY_BASE_ADRESS),HEX2DEC(AZ27))) -> 1EEF3
B28: 0 | C28: =C27 -> 12 | D28: =IF(D27=30,0,30) -> 30 | E28: =SUM(E27+1) -> 25 | F28: =DEC2HEX(SUM((B28*slots_per_day_1phase)+E28)*numberofbytes_tostore_1phase) -> 41A | G28: =DEC2HEX(SUM(HEX2DEC(LOAD_SURVEY_BASE_ADRESS),HEX2DEC(F28))) -> 169D | I28: 1 | J28: =J27 -> 12 | K28: =IF(K27=30,0,30) -> 30 | L28: =SUM(L27+1) -> 25 | M28: =DEC2HEX(SUM((I28*slots_per_day_1phase)+L28)*numberofbytes_tostore_1phase) -> BFA | N28: =DEC2HEX(SUM(HEX2DEC(LOAD_SURVEY_BASE_ADRESS),HEX2DEC(M28))) -> 1E7D | P28: =SUM(P27+0) -> 2 | Q28: =Q27 -> 12 | R28: =IF(R27=30,0,30) -> 30 | S28: =SUM(S27+1) -> 25 | T28: =DEC2HEX(SUM((P28*slots_per_day_1phase)+S28)*numberofbytes_tostore_1phase) -> 13DA | U28: =DEC2HEX(SUM(HEX2DEC(LOAD_SURVEY_BASE_ADRESS),HEX2DEC(T28))) -> 265D | X28: =SUM(X27+0) -> 7 | Y28: =Y27 -> 12 | Z28: =IF(Z27=30,0,30) -> 30 | AA28: =SUM(AA27+1) -> 25 | AB28: =DEC2HEX(SUM((X28*slots_per_day_1phase)+AA28)*numberofbytes_tostore_1phase) -> 3B3A | AC28: =DEC2HEX(SUM(HEX2DEC(LOAD_SURVEY_BASE_ADRESS),HEX2DEC(AB28))) -> 4DBD | AF28: =SUM(AF27+0) -> 21 | AG28: =AG27 -> 12 | AH28: =IF(AH27=30,0,30) -> 30 | AI28: =SUM(AI27+1) -> 25 | AJ28: =DEC2HEX(SUM((AF28*slots_per_day_1phase)+AI28)*numberofbytes_tostore_1phase) -> A97A | AK28: =DEC2HEX(SUM(HEX2DEC(LOAD_SURVEY_BASE_ADRESS),HEX2DEC(AJ28))) -> BBFD | AN28: =SUM(AN27+0) -> 34 | AO28: =AO27 -> 12 | AP28: =IF(AP27=30,0,30) -> 30 | AQ28: =SUM(AQ27+1) -> 25 | AR28: =DEC2HEX(SUM((AN28*slots_per_day_1phase)+AQ28)*numberofbytes_tostore_1phase) -> 10FDA | AS28: =DEC2HEX(SUM(HEX2DEC(LOAD_SURVEY_BASE_ADRESS),HEX2DEC(AR28))) -> 1225D | AV28: =SUM(AV27+0) -> 60 | AW28: =AW27 -> 12 | AX28: =IF(AX27=30,0,30) -> 30 | AY28: =SUM(AY27+1) -> 25 | AZ28: =DEC2HEX(SUM((AV28*slots_per_day_1phase)+AY28)*numberofbytes_tostore_1phase) -> 1DC9A | BA28: =DEC2HEX(SUM(HEX2DEC(LOAD_SURVEY_BASE_ADRESS),HEX2DEC(AZ28))) -> 1EF1D
B29: 0 | C29: =SUM(C27+1) -> 13 | D29: =IF(D28=30,0,30) -> 0 | E29: =SUM(E28+1) -> 26 | F29: =DEC2HEX(SUM((B29*slots_per_day_1phase)+E29)*numberofbytes_tostore_1phase) -> 444 | G29: =DEC2HEX(SUM(HEX2DEC(LOAD_SURVEY_BASE_ADRESS),HEX2DEC(F29))) -> 16C7 | I29: 1 | J29: =SUM(J27+1) -> 13 | K29: =IF(K28=30,0,30) -> 0 | L29: =SUM(L28+1) -> 26 | M29: =DEC2HEX(SUM((I29*slots_per_day_1phase)+L29)*numberofbytes_tostore_1phase) -> C24 | N29: =DEC2HEX(SUM(HEX2DEC(LOAD_SURVEY_BASE_ADRESS),HEX2DEC(M29))) -> 1EA7 | P29: =SUM(P28+0) -> 2 | Q29: =SUM(Q27+1) -> 13 | R29: =IF(R28=30,0,30) -> 0 | S29: =SUM(S28+1) -> 26 | T29: =DEC2HEX(SUM((P29*slots_per_day_1phase)+S29)*numberofbytes_tostore_1phase) -> 1404 | U29: =DEC2HEX(SUM(HEX2DEC(LOAD_SURVEY_BASE_ADRESS),HEX2DEC(T29))) -> 2687 | X29: =SUM(X28+0) -> 7 | Y29: =SUM(Y27+1) -> 13 | Z29: =IF(Z28=30,0,30) -> 0 | AA29: =SUM(AA28+1) -> 26 | AB29: =DEC2HEX(SUM((X29*slots_per_day_1phase)+AA29)*numberofbytes_tostore_1phase) -> 3B64 | AC29: =DEC2HEX(SUM(HEX2DEC(LOAD_SURVEY_BASE_ADRESS),HEX2DEC(AB29))) -> 4DE7 | AF29: =SUM(AF28+0) -> 21 | AG29: =SUM(AG27+1) -> 13 | AH29: =IF(AH28=30,0,30) -> 0 | AI29: =SUM(AI28+1) -> 26 | AJ29: =DEC2HEX(SUM((AF29*slots_per_day_1phase)+AI29)*numberofbytes_tostore_1phase) -> A9A4 | AK29: =DEC2HEX(SUM(HEX2DEC(LOAD_SURVEY_BASE_ADRESS),HEX2DEC(AJ29))) -> BC27 | AN29: =SUM(AN28+0) -> 34 | AO29: =SUM(AO27+1) -> 13 | AP29: =IF(AP28=30,0,30) -> 0 | AQ29: =SUM(AQ28+1) -> 26 | AR29: =DEC2HEX(SUM((AN29*slots_per_day_1phase)+AQ29)*numberofbytes_tostore_1phase) -> 11004 | AS29: =DEC2HEX(SUM(HEX2DEC(LOAD_SURVEY_BASE_ADRESS),HEX2DEC(AR29))) -> 12287 | AV29: =SUM(AV28+0) -> 60 | AW29: =SUM(AW27+1) -> 13 | AX29: =IF(AX28=30,0,30) -> 0 | AY29: =SUM(AY28+1) -> 26 | AZ29: =DEC2HEX(SUM((AV29*slots_per_day_1phase)+AY29)*numberofbytes_tostore_1phase) -> 1DCC4 | BA29: =DEC2HEX(SUM(HEX2DEC(LOAD_SURVEY_BASE_ADRESS),HEX2DEC(AZ29))) -> 1EF47
